Workbook
Name AHSP: AHSP!$E$8:$M$8073
Name Bahan: BAHAN!$F$6:$K$510
Name k_bgl_kolom_1515: 'PERH. TULANGAN'!#REF!
Name k_bgl_sloof_1520: 'PERH. TULANGAN'!#REF!
Name k_tlg_kolom_1515: 'PERH. TULANGAN'!$O$8
Name k_tlg_sloof_d10: 'PERH. TULANGAN'!$O$7
Name RekapVolume: 'REKAP VOLUME'!$F$6:$H$117
Name TB: DATA!#REF!
Name TB: REKAPITULASI!#REF!
Name TB: HOME!#REF!
Name Upah: UPAH!$G$6:$N$45
Name v__balok2030: '[1]vol pek'!$C$58
Name v__kolom2550: '[1]vol pek'!$C$44
Name V_ACIAN: '[1]vol pek'!$C$115
Name v_atap: '[1]vol pek'!$C$101
Name v_bakcucipiring: '[1]vol pek'!$C$158
Name v_bakkontrol: '[1]vol pek'!$C$168
Name v_balok1520: '[1]vol pek'!$C$53
Name v_balok1525: '[1]vol pek'!$C$54
Name v_balok1530: '[1]vol pek'!$C$55
Name v_balok2020: '[1]vol pek'!$C$56
Name v_balok2025: '[1]vol pek'!$C$57
Name v_balok2035: '[1]vol pek'!$C$59
Name v_balok2040: '[1]vol pek'!$C$60
Name v_balok2525: '[1]vol pek'!$C$61
Name v_balok2535: '[1]vol pek'!$C$63
Name v_balok2540: '[1]vol pek'!$C$64
Name v_balok2545: '[1]vol pek'!$C$65
Name v_balok2550: '[1]vol pek'!$C$66
Name v_balok3035: '[1]vol pek'!$C$68
Name v_balok3040: '[1]vol pek'!$C$69
Name v_balok3545: '[1]vol pek'!$C$70
Name v_balok3550: '[1]vol pek'!$C$71
Name v_balok4040: '[1]vol pek'!$C$72
Name v_balok4045: '[1]vol pek'!$C$73
Name v_balok4050: '[1]vol pek'!$C$74
Name v_balokdinding: '[1]vol pek'!$C$93
Name v_blk_3030: '[1]vol pek'!$C$67
Name v_cat_kayu: '[1]vol pek'!$C$141
Name v_cat_tembok: '[1]vol pek'!$C$143
Name v_dempul: '[1]vol pek'!$C$139
Name v_dinding_1_2: '[1]vol pek'!$C$85
Name v_dinding_1_4: '[1]vol pek'!$C$84
Name v_dinding1_2: '[1]vol pek'!$C$113
Name v_dinding1_4: '[1]vol pek'!$C$114
Name v_engsel: '[1]vol pek'!$C$134
Name v_floordrain: '[1]vol pek'!$C$157
Name v_galian_2m: '[1]vol pek'!$C$14
Name v_galian_3m: '[1]vol pek'!$C$15
Name v_galian_cadas: '[1]vol pek'!$C$17
Name v_galian_keras: '[1]vol pek'!$C$16
Name v_galian_lumpur: '[1]vol pek'!$C$18
Name v_galiantanahpondasi: '[1]vol pek'!$C$13
Name v_gording: '[1]vol pek'!$C$98
Name v_gudangsemen: '[1]vol pek'!$C$9
Name v_kaca_15mm: '[1]vol pek'!$C$132
Name v_keran: '[1]vol pek'!$C$163
Name v_klosetduduk: '[1]vol pek'!$C$156
Name v_klosetjongkok: '[1]vol pek'!$C$155
Name v_kolom1515: '[1]vol pek'!$C$30

Sheet HOME
E2: HOME
A21: www.rabotomatis.com

Sheet DATA
E2: DATA
A29: www.rabotomatis.com

Sheet AHSP
E2: AHSP (Analisa Harga Satuan Pekerjaan)
F4: ANALISA HARGA SATUAN PEKERJAAN (AHSP)
D7: A.2.2.1 | E7: HARGA SATUAN PEKERJAAN PERSIAPAN
E8: A.1.1.1.1 | F8: (K3) Pembuatan 1 m2 pagar sementara dari kayu tinggi 2 meter | M8: =L29 -> 698740
E9: A.1.1.1.1 | F9: No | G9: Uraian | H9: Kode | I9: Satuan | J9: Koefisien | K9: Harga Satuan (Rp.) | L9: Jumlah Harga (Rp.)
E10: A.1.1.1.1 | F10: A | G10: TENAGA
E11: A.1.1.1.1 | G11: Pekerja | H11: L.01.01 | I11: OH | J11: 0.4 | K11: =VLOOKUP(G11,Upah,8,FALSE) -> 125000 | L11: =J11*K11 -> 50000
E12: A.1.1.1.1 | G12: Tukang Kayu | H12: L.02.04 | I12: OH | J12: 0.2 | K12: =VLOOKUP(G12,Upah,8,FALSE) -> 150000 | L12: =J12*K12 -> 30000
E13: A.1.1.1.1 | G13: Kepala Tukang | H13: L.03.01 | I13: OH | J13: 0.02 | K13: =VLOOKUP(G13,Upah,8,FALSE) -> 165000 | L13: =J13*K13 -> 3300
E14: A.1.1.1.1 | G14: Mandor | H14: L.04.01 | I14: OH | J14: 0.02 | K14: =VLOOKUP(G14,Upah,8,FALSE) -> 170000 | L14: =J14*K14 -> 3400
E15: A.1.1.1.1 | J15: JUMLAH TENAGA KERJA | L15: =SUM(L11:L14) -> 86700
E16: A.1.1.1.1 | F16: B | G16: BAHAN
E17: A.1.1.1.1 | G17: Dolken kayu Ø 8-10/400 cm | I17: Batang | J17: 1.25 | K17: =VLOOKUP(G17,Bahan,6,FALSE) -> 31250 | L17: =J17*K17 -> 39062.5
E18: A.1.1.1.1 | G18: Semen portland | I18: Kg | J18: 5 | K18: =VLOOKUP(G18,Bahan,6,FALSE) -> 1880 | L18: =J18*K18 -> 9400
E19: A.1.1.1.1 | G19: Pasir beton m3 | I19: m3 | J19: 0.005 | K19: =VLOOKUP(G19,Bahan,6,FALSE) -> 350000 | L19: =J19*K19 -> 1750
E20: A.1.1.1.1 | G20: Koral beton | I20: m3 | J20: 0.009 | K20: =VLOOKUP(G20,Bahan,6,FALSE) -> 600000 | L20: =J20*K20 -> 5400
E21: A.1.1.1.1 | G21: Kayu 5/7 | I21: m3 | J21: 0.072 | K21: =VLOOKUP(G21,Bahan,6,FALSE) -> 6765000 | L21: =J21*K21 -> 487080
E22: A.1.1.1.1 | G22: Paku biasa | I22: Kg | J22: 0.06 | K22: =VLOOKUP(G22,Bahan,6,FALSE) -> 27970 | L22: =J22*K22 -> 1678.2
E23: A.1.1.1.1 | G23: Residu | I23: Liter | J23: 0.4 | K23: =VLOOKUP(G23,Bahan,6,FALSE) -> 10370 | L23: =J23*K23 -> 4148
E24: A.1.1.1.1 | J24: JUMLAH HARGA BAHAN | L24: =SUM(L16:L23) -> 548518.7
E25: A.1.1.1.1 | F25: C | G25: PERALATAN
E26: A.1.1.1.1 | J26: JUMLAH HARGA ALAT | L26: =L25 -> 0
E27: A.1.1.1.1 | F27: D | G27: Jumlah (A+B+C) | L27: =SUM(L11:L26)/2 -> 635218.7
E28: A.1.1.1.1 | F28: E | G28: Overhead & Profit 10% | J28: 0.1 | L28: =J28*L27 -> 63521.87
A29: www.rabotomatis.com | E29: A.1.1.1.1 | F29: F | G29: Harga Satuan Pekerjaan (D+E) | K29: 0 | L29: =ROUNDDOWN(L27+L28,0) -> 698740
E31: A.1.1.1.2 | F31: (K3) Pembuatan 1 m2 pagar sementara dari seng gelombang tinggi 2 meter | M31: =L53 -> 795702
E32: A.1.1.1.2 | F32: No | G32: Uraian | H32: Kode | I32: Satuan | J32: Koefisien | K32: Harga Satuan (Rp.) | L32: Jumlah Harga (Rp.)
E33: A.1.1.1.2 | F33: A | G33: TENAGA | K33: 0 | L33: =J33*K33 -> 0
E34: A.1.1.1.2 | G34: Pekerja | H34: L.01.01 | I34: OH | J34: 0.2 | K34: =VLOOKUP(G34,Upah,8,FALSE) -> 125000 | L34: =J34*K34 -> 25000
E35: A.1.1.1.2 | G35: Tukang Kayu | H35: L.02.04 | I35: OH | J35: 0.4 | K35: =VLOOKUP(G35,Upah,8,FALSE) -> 150000 | L35: =J35*K35 -> 60000
E36: A.1.1.1.2 | G36: Kepala Tukang | H36: L.03.01 | I36: OH | J36: 0.02 | K36: =VLOOKUP(G36,Upah,8,FALSE) -> 165000 | L36: =J36*K36 -> 3300
E37: A.1.1.1.2 | G37: Mandor | H37: L.04.01 | I37: OH | J37: 0.02 | K37: =VLOOKUP(G37,Upah,8,FALSE) -> 170000 | L37: =J37*K37 -> 3400
E38: A.1.1.1.2 | J38: JUMLAH TENAGA KERJA | L38: =SUM(L33:L37) -> 91700
E39: A.1.1.1.2 | F39: B | G39: BAHAN
E40: A.1.1.1.2 | G40: Dolken kayu Ø 8-10/400 cm | I40: Batang | J40: 1.25 | K40: =VLOOKUP(G40,Bahan,6,FALSE) -> 31250 | L40: =J40*K40 -> 39062.5
E41: A.1.1.1.2 | G41: Semen portland | I41: Kg | J41: 2.5 | K41: =VLOOKUP(G41,Bahan,6,FALSE) -> 1880 | L41: =J41*K41 -> 4700
E42: A.1.1.1.2 | G42: Seng gelombang | I42: Lbr | J42: 1.2 | K42: =VLOOKUP(G42,Bahan,6,FALSE) -> 63500 | L42: =J42*K42 -> 76200
E43: A.1.1.1.2 | G43: Pasir beton m3 | I43: m3 | J43: 0.005 | K43: =VLOOKUP(G43,Bahan,6,FALSE) -> 350000 | L43: =J43*K43 -> 1750
E44: A.1.1.1.2 | G44: Koral beton | I44: m3 | J44: 0.009 | K44: =VLOOKUP(G44,Bahan,6,FALSE) -> 600000 | L44: =J44*K44 -> 5400
E45: A.1.1.1.2 | G45: Kayu 5/7 | I45: m3 | J45: 0.072 | K45: =VLOOKUP(G45,Bahan,6,FALSE) -> 6765000 | L45: =J45*K45 -> 487080
...

Sheet HSP
E2: HSP (Harga Satuan Pekerjaan)
E4: No | F4: Kode | H4: Jenis Pekerjaan | I4: Satuan | J4: Harga
F6: A.1.1.1 | G6: HARGA SATUAN PEKERJAAN PERSIAPAN
E7: 1 | G7: A.1.1.1.1 | H7: =VLOOKUP(G7,AHSP,2,FALSE) -> (K3) Pembuatan 1 m2 pagar sementara dari kayu tinggi 2 meter | I7: m2 | J7: =VLOOKUP(G7,AHSP,9,FALSE) -> 698740
E8: =E7+1 -> 2 | G8: A.1.1.1.2 | H8: =VLOOKUP(G8,AHSP,2,FALSE) -> (K3) Pembuatan 1 m2 pagar sementara dari seng gelombang tinggi 2 meter | I8: m2 | J8: =VLOOKUP(G8,AHSP,9,FALSE) -> 795702
E9: =E8+1 -> 3 | G9: A.1.1.1.3 | H9: =VLOOKUP(G9,AHSP,2,FALSE) -> Pembuatan 1 m2 pagar sementara dari kawat duri tinggi 1,8 meter | I9: m2 | J9: =VLOOKUP(G9,AHSP,9,FALSE) -> 814561
E10: =E9+1 -> 4 | G10: A.1.1.1.4 | H10: =VLOOKUP(G10,AHSP,2,FALSE) -> Pengukuran dan pemasangan 1 m’ Bouwplank | I10: m2 | J10: =VLOOKUP(G10,AHSP,9,FALSE) -> 92990
E11: =E10+1 -> 5 | G11: A.1.1.1.5 | H11: =VLOOKUP(G11,AHSP,2,FALSE) -> (K3) Pembuatan 1 m2 kantor sementara lantai plesteran | I11: m2 | J11: =VLOOKUP(G11,AHSP,9,FALSE) -> 2574354
E12: =E11+1 -> 6 | G12: A.1.1.1.6 | H12: =VLOOKUP(G12,AHSP,2,FALSE) -> (K3) Pembuatan 1 m2 gudang | I12: m2 | J12: =VLOOKUP(G12,AHSP,9,FALSE) -> 2323646
E13: =E12+1 -> 7 | G13: A.1.1.1.7 | H13: =VLOOKUP(G13,AHSP,2,FALSE) -> (K3) Pembuatan 1 m2 rumah jaga (konstruksi kayu ) | I13: m2 | J13: =VLOOKUP(G13,AHSP,9,FALSE) -> 2704865
E14: =E13+1 -> 8 | G14: A.1.1.1.8 | H14: =VLOOKUP(G14,AHSP,2,FALSE) -> Pembersihan 1 m2 dan peralatan lapangan | I14: m2 | J14: =VLOOKUP(G14,AHSP,9,FALSE) -> 23100
E15: =E14+1 -> 9 | G15: A.1.1.1.9 | H15: =VLOOKUP(G15,AHSP,2,FALSE) -> (K3) Pembuatan 1 m2 bedeng pekerja | I15: m2 | J15: =VLOOKUP(G15,AHSP,9,FALSE) -> 2251846
E16: =E15+1 -> 10 | G16: A.1.1.1.10 | H16: =VLOOKUP(G16,AHSP,2,FALSE) -> Pembuatan 1 m2 bak adukan | I16: m2 | J16: =VLOOKUP(G16,AHSP,9,FALSE) -> 244258
E17: =E16+1 -> 11 | G17: A.1.1.1.11 | H17: =VLOOKUP(G17,AHSP,2,FALSE) -> Pembuatan 1 m2 perancah dari bambu s.d. tinggi 6 meter | I17: m2 | J17: =VLOOKUP(G17,AHSP,9,FALSE) -> 548811
E18: =E17+1 -> 12 | G18: A.1.1.1.12 | H18: =VLOOKUP(G18,AHSP,2,FALSE) -> Pembuatan 1 m2 jalan sementara | I18: m2 | J18: =VLOOKUP(G18,AHSP,9,FALSE) -> 251658
E19: =E18+1 -> 13 | G19: A.1.1.1.13 | H19: =VLOOKUP(G19,AHSP,2,FALSE) -> Pembongkaran 1 m3 beton bertulang | I19: m3 | J19: =VLOOKUP(G19,AHSP,9,FALSE) -> 331644
... E22: =E21+1 -> 16 | G22: A.1.1.1.16 | H22: =VLOOKUP(G22,AHSP,2,FALSE) -> Pemasangan 1 m2 panel beton pracetak 50x50x240 cm | I22: m2 | J22: =VLOOKUP(G22,AHSP,9,FALSE) -> 626811
F24: A.1.5.1 | G24: HARGA SATUAN PEKERJAAN TANAH
E25: 17 | G25: A.1.5.1.1 | H25: =VLOOKUP(G25,AHSP,2,FALSE) -> Penggalian 1 m3 tanah biasa sedalam s.d. 1 m | I25: m3 | J25: =VLOOKUP(G25,AHSP,9,FALSE) -> 107800
E26: =E25+1 -> 18 | G26: A.1.5.1.2 | H26: =VLOOKUP(G26,AHSP,2,FALSE) -> Penggalian 1 m3 tanah biasa sedalam >1 s.d. 2 m | I26: m3 | J26: =VLOOKUP(G26,AHSP,9,FALSE) -> 132165
E27: =E26+1 -> 19 | G27: A.1.5.1.3 | H27: =VLOOKUP(G27,AHSP,2,FALSE) -> Penggalian 1 m3 tanah biasa sedalam >2 s.d. 3 m | I27: m3 | J27: =VLOOKUP(G27,AHSP,9,FALSE) -> 156904
E28: =E27+1 -> 20 | G28: A.1.5.1.4 | H28: =VLOOKUP(G28,AHSP,2,FALSE) -> Penggalian 1 m3 tanah keras sedalam s.d. 1 m | I28: m3 | J28: =VLOOKUP(G28,AHSP,9,FALSE) -> 143484
A29: www.rabotomatis.com | E29: =E28+1 -> 21 | G29: A.1.5.1.5 | H29: =VLOOKUP(G29,AHSP,2,FALSE) -> Penggalian 1 m3 tanah cadas sedalam s.d. 1 m | I29: m3 | J29: =VLOOKUP(G29,AHSP,9,FALSE) -> 217470
E30: =E29+1 -> 22 | G30: A.1.5.1.6 | H30: =VLOOKUP(G30,AHSP,2,FALSE) -> Penggalian 1 m3 tanah lumpur sedalam s.d. 1 m | I30: m3 | J30: =VLOOKUP(G30,AHSP,9,FALSE) -> 173415
E31: =E30+1 -> 23 | G31: A.1.5.1.7 | H31: =VLOOKUP(G31,AHSP,2,FALSE) -> Pengerjaan stripping 1 m2 tanah tebing setinggi s.d. 1 meter | I31: m2 | J31: =VLOOKUP(G31,AHSP,9,FALSE) -> 7810
E32: =E31+1 -> 24 | G32: A.1.5.1.8 | H32: =VLOOKUP(G32,AHSP,2,FALSE) -> (K3) Pembuangan 1 m3 tanah sejauh s.d. 30 meter | I32: m3 | J32: =VLOOKUP(G32,AHSP,9,FALSE) -> 47245
E33: =E32+1 -> 25 | G33: A.1.5.1.9 | H33: =VLOOKUP(G33,AHSP,2,FALSE) -> Pengurugan kembali 1 m3 galian tanah Tanah Biasa Sedalam 1 M | I33: m3 | J33: =VLOOKUP(G33,AHSP,9,FALSE) -> 39050
E34: =E33+1 -> 26 | G34: A.1.5.1.10 | H34: =VLOOKUP(G34,AHSP,2,FALSE) -> (K3) Pemadatan tanah 1 m3 tanah ( per 20 cm) | I34: m3 | J34: =VLOOKUP(G34,AHSP,9,FALSE) -> 78100
E35: =E34+1 -> 27 | G35: A.1.5.1.11 | H35: =VLOOKUP(G35,AHSP,2,FALSE) -> Pengurugan 1 m3 dengan pasir urug | I35: m3 | J35: =VLOOKUP(G35,AHSP,9,FALSE) -> 440426
E36: =E35+1 -> 28 | G36: A.1.5.1.12 | H36: =VLOOKUP(G36,AHSP,2,FALSE) -> Pemasangan 1 m3 lapisan pudel campuran 1KP:3PP:7TL | I36: m3 | J36: =VLOOKUP(G36,AHSP,9,FALSE) -> 418145
E37: =E36+1 -> 29 | G37: A.1.5.1.13 | H37: =VLOOKUP(G37,AHSP,2,FALSE) -> Pemasangan 1 m2 lapisan ijuk tebal 10 cm untuk bidang resapan | I37: m2 | J37: =VLOOKUP(G37,AHSP,9,FALSE) -> 1617330
E38: =E37+1 -> 30 | G38: A.1.5.1.14 | H38: =VLOOKUP(G38,AHSP,2,FALSE) -> Pengurugan 1 m3 dengan sirtu padat | I38: m3 | J38: =VLOOKUP(G38,AHSP,9,FALSE) -> 401852
F40: A.3.1.1 | G40: HARGA SATUAN PEKERJAAN PONDASI
E41: 31 | G41: A.3.1.1.1 | H41: =VLOOKUP(G41,AHSP,2,FALSE) -> Pemasangan 1 m3 pondasi batu belah campuran 1SP : 3PP | I41: m3 | J41: =VLOOKUP(G41,AHSP,9,FALSE) -> 1467001
E42: =E41+1 -> 32 | G42: A.3.1.1.2 | H42: =VLOOKUP(G42,AHSP,2,FALSE) -> Pemasangan 1 m3 pondasi batu belah campuran 1SP : 4PP | I42: m3 | J42: =VLOOKUP(G42,AHSP,9,FALSE) -> 1396109
E43: =E42+1 -> 33 | G43: A.3.1.1.3 | H43: =VLOOKUP(G43,AHSP,2,FALSE) -> Pemasangan 1 m3 pondasi batu belah campuran 1SP : 5PP | I43: m3 | J43: =VLOOKUP(G43,AHSP,9,FALSE) -> 1346965
E44: =E43+1 -> 34 | G44: A.3.1.1.4 | H44: =VLOOKUP(G44,AHSP,2,FALSE) -> Pemasangan 1 m3 pondasi batu belah campuran 1SP : 6PP | I44: m3 | J44: =VLOOKUP(G44,AHSP,9,FALSE) -> 1312414
E45: =E44+1 -> 35 | G45: A.3.1.1.5 | H45: =VLOOKUP(G45,AHSP,2,FALSE) -> Pemasangan 1 m3 pondasi batu belah campuran 1SP : 8PP | I45: m3 | J45: =VLOOKUP(G45,AHSP,9,FALSE) -> 1265060
E46: =E45+1 -> 36 | G46: A.3.1.1.6 | H46: =VLOOKUP(G46,AHSP,2,FALSE) -> Pemasangan 1 m3 pondasi batu belah campuran 1SP : 1KP : 2PP | I46: m3 | J46: =VLOOKUP(G46,AHSP,9,FALSE) -> 1444343
E47: =E46+1 -> 37 | G47: A.3.1.1.7 | H47: =VLOOKUP(G47,AHSP,2,FALSE) -> Pemasangan 1 m3 pondasi batu belah campuran 1 SP : 3 KP : 10 PP | I47: m3 | J47: =VLOOKUP(G47,AHSP,9,FALSE) -> 1249960
...

Sheet BAHAN
E2: HARGA BAHAN
E4: No. | F4: HARGA BAHAN | J4: Satuan | K4: Harga Satuan | L4: Keterangan
E6: 1 | F6: Air | J6: Liter | K6: 75
E7: =E6+1 -> 2 | F7: Air Kerja | J7: Liter | K7: 75
E8: =E7+1 -> 3 | F8: Air test (air bersih) | J8: m3 | K8: 35000
E9: =E8+1 -> 4 | F9: Air Bersih / PDAM | J9: Liter | K9: 3500
E10: =E9+1 -> 5 | F10: Akustik 60 x 120 | J10: Lembar | K10: 157440
E11: =E10+1 -> 6 | F11: Akustik ukuran 30 x 30 cm | J11: Lembar | K11: 42700
E12: =E11+1 -> 7 | F12: Akustik ukuran 30 x 60 cm | J12: Lembar | K12: 65450
E13: =E12+1 -> 8 | F13: Alang-alang | J13: Ikat | K13: 680
E14: =E13+1 -> 9 | F14: Aluminium Composite Panel | J14: Lbr | K14: 384810
E15: =E14+1 -> 10 | F15: Aluminium strip | J15: m | K15: 28930
E16: =E15+1 -> 11 | F16: Alumunium foil | J16: M2 | K16: 32890
E17: =E16+1 -> 12 | F17: Alumunium gel tbl 0,55 | J17: Lbr | K17: 171100
E18: =E17+1 -> 13 | F18: Ampelas | J18: Lbr | K18: 8260
... E28: =E27+1 -> 23 | F28: Bak fibreglass | J28: Unit | K28: 393600
A29: www.rabotomatis.com | E29: =E28+1 -> 24 | F29: Balok kayu kelas I | J29: m3 | K29: 6500000
E30: =E29+1 -> 25 | F30: Balok kayu kelas II | J30: m3 | K30: 4410000
E31: =E30+1 -> 26 | F31: Balok kayu, 6 x 12 | J31: m3 | K31: 5715000
E32: =E31+1 -> 27 | F32: Bambu diameter 6 - 8 / 600 cm | J32: Batang | K32: 22140
E33: =E32+1 -> 28 | F33: Bata ringan tebal 7,5 cm | J33: bh | K33: 9000
E34: =E33+1 -> 29 | F34: Bata berongga | J34: bh | K34: 1820
E35: =E34+1 -> 30 | F35: Bata merah | J35: Bh | K35: 1040
E36: =E35+1 -> 31 | F36: Bata pelapis Dinding 3cm x 7cm x 24cm | J36: Bh | K36: 840
E37: =E36+1 -> 32 | F37: Bata rooster | J37: Bh | K37: 860
E38: =E37+1 -> 33 | F38: Bathcuip | J38: Unit | K38: 3355000
E39: =E38+1 -> 34 | F39: Batu belah | J39: m3 | K39: 421500
E40: =E39+1 -> 35 | F40: Batu gunung | J40: m3 | K40: 421500
E41: =E40+1 -> 36 | F41: Batu granit | J41: Kg | K41: 18750
... E125: =E124+1 -> 120 | F125: Kayu 5/7 | J125: m3 | K125: 6765000
E126: =E125+1 -> 121 | F126: Kayu balok 5/7 | J126: m3 | K126: =K125 -> 6765000
E127: =E126+1 -> 122 | F127: Kayu balok 5/7 kelas III | J127: m3 | K127: 2646000
E128: =E127+1 -> 123 | F128: Kayu balok borneo | J128: M3 | K128: 4375000
E129: =E128+1 -> 124 | F129: Kayu bekisting | J129: M2 | K129: 1500000
E130: =E129+1 -> 125 | F130: Kayu kaso 5/7 | J130: m3 | K130: 4375000
E131: =E130+1 -> 126 | F131: Kayu kelas II | J131: m3 | K131: 5500000
E132: =E131+1 -> 127 | F132: Kayu kelas II balok | J132: M3 | K132: 5500000
E133: =E132+1 -> 128 | F133: Kayu kelas III | J133: m3 | K133: 4500000
E134: =E133+1 -> 129 | F134: Kayu kelas III (papan) | J134: m3 | K134: 4500000
E135: =E134+1 -> 130 | F135: Kayu papan | J135: m3 | K135: 4500000
...

Sheet UPAH
E2: UPAH PEKERJA
E4: No. | F4: Tenaga Kerja | K4: Kode | L4: Satuan | M4: Harga Satuan (Rp.) | O4: Keterangan | Q4: Jam Kerja Eff. | R4: 8
E6: 1 | G6: Pekerja | K6: L.01 | L6: OH | M6: =TRUNC(N6/$R$4,-2) -> 15600 | N6: 125000
E7: =E6+1 -> 2 | G7: Pekerja Anyam | K7: L.01 | L7: OH | M7: =TRUNC(N7/$R$4,-2) -> 15600 | N7: 125000
E8: =E7+1 -> 3 | G8: Pekerja Pengisi Batu | K8: L.01 | L8: OH | M8: =TRUNC(N8/$R$4,-2) -> 15600 | N8: 125000
E9: =E8+1 -> 4 | G9: Tukang | K9: L.02 | L9: OH | M9: =TRUNC(N9/$R$4,-2) -> 18700 | N9: 150000
E10: =E9+1 -> 5 | G10: Tukang Gali | K10: L.02 | L10: OH | M10: =TRUNC(N10/$R$4,-2) -> 15600 | N10: =$N$6 -> 125000
E11: =E10+1 -> 6 | G11: Tukang Batu | K11: L.02 | L11: OH | M11: =TRUNC(N11/$R$4,-2) -> 18700 | N11: =$N$9 -> 150000
E12: =E11+1 -> 7 | G12: Tukang Kayu | K12: L.02 | L12: OH | M12: =TRUNC(N12/$R$4,-2) -> 18700 | N12: =$N$9 -> 150000
E13: =E12+1 -> 8 | G13: Tukang Besi | K13: L.02 | L13: OH | M13: =TRUNC(N13/$R$4,-2) -> 18700 | N13: =$N$9 -> 150000
E14: =E13+1 -> 9 | G14: Tukang Besi Konstruksi | K14: L.02 | L14: OH | M14: =TRUNC(N14/$R$4,-2) -> 18700 | N14: =$N$9 -> 150000
E15: =E14+1 -> 10 | G15: Tukang Alumunium | K15: L.02 | L15: OH | M15: =TRUNC(N15/$R$4,-2) -> 18700 | N15: =$N$9 -> 150000
E16: =E15+1 -> 11 | G16: Tukang Cat | K16: L.02 | L16: OH | M16: =TRUNC(N16/$R$4,-2) -> 18700 | N16: =$N$9 -> 150000
E17: =E16+1 -> 12 | G17: Tukang Pipa | K17: L.02 | L17: OH | M17: =TRUNC(N17/$R$4,-2) -> 18700 | N17: =$N$9 -> 150000
E18: =E17+1 -> 13 | G18: Tukang Pengayam Bronjong | K18: L.02 | L18: OH | M18: =TRUNC(N18/$R$4,-2) -> 18700 | N18: =$N$9 -> 150000
E19: =E18+1 -> 14 | G19: Tukang Tebas | K19: L.02 | L19: OH | M19: =TRUNC(N19/$R$4,-2) -> 15600 | N19: =$N$6 -> 125000
E20: =E19+1 -> 15 | G20: Tukang Vibrator | K20: L.02 | L20: OH | M20: =TRUNC(N20/$R$4,-2) -> 18700 | N20: =$N$9 -> 150000
E21: =E20+1 -> 16 | G21: Tukang Ereksi | K21: L.02 | L21: OH | M21: =TRUNC(N21/$R$4,-2) -> 18700 | N21: =$N$9 -> 150000
E22: =E21+1 -> 17 | G22: Tukang Las | K22: L.02 | L22: OH | M22: =TRUNC(N22/$R$4,-2) -> 18700 | N22: =$N$9 -> 150000
E23: =E22+1 -> 18 | G23: Tukang Las Konstruksi | K23: L.02 | L23: OH | M23: =TRUNC(N23/$R$4,-2) -> 18700 | N23: =$N$9 -> 150000
E24: =E23+1 -> 19 | G24: Kepala Tukang | K24: L.03 | L24: OH | M24: =TRUNC(N24/$R$4,-2) -> 20600 | N24: =N9+15000 -> 165000
E25: =E24+1 -> 20 | G25: Mandor | K25: L.04 | L25: OH | M25: =TRUNC(N25/$R$4,-2) -> 21200 | N25: =N9+20000 -> 170000
E26: =E25+1 -> 21 | G26: Juru Ukur | K26: L.05 | L26: OH | M26: =TRUNC(N26/$R$4,-2) -> 20600 | N26: =$N$9*1.1 -> 165000
E27: =E26+1 -> 22 | G27: Pembantu Juru Ukur | K27: L.06 | L27: OH | M27: =TRUNC(N27/$R$4,-2) -> 20600 | N27: =$N$9*1.1 -> 165000
E28: =E27+1 -> 23 | G28: Ahli Alat Berat ( Mekanik ) | K28: L.07 | L28: OH | M28: =TRUNC(N28/$R$4,-2) -> 20600 | N28: =$N$9*1.1 -> 165000
A29: www.rabotomatis.com | E29: =E28+1 -> 24 | G29: Operator Alat Berat | K29: L.08 | L29: OH | M29: =TRUNC(N29/$R$4,-2) -> 20600 | N29: =$N$24 -> 165000
E30: =E29+1 -> 25 | G30: Pembantu Operator | K30: L.09 | L30: OH | M30: =TRUNC(N30/$R$4,-2) -> 18500 | N30: =$N$29*0.9 -> 148500
E31: =E30+1 -> 26 | G31: Operator Alat Pipa | K31: L.08 | L31: OH | M31: =TRUNC(N31/$R$4,-2) -> 20600 | N31: =$N$24 -> 165000
E32: =E31+1 -> 27 | G32: Sopir Truck | K32: L.10 | L32: OH | M32: =TRUNC(N32/$R$4,-2) -> 20600 | N32: =$N$9*1.1 -> 165000
E33: =E32+1 -> 28 | G33: Kenek Truk | K33: L.11 | L33: OH | M33: =TRUNC(N33/$R$4,-2) -> 20600 | N33: =$N$9*1.1 -> 165000
E34: =E33+1 -> 29 | G34: Penjaga Malam | K34: L.12 | L34: OH | M34: =TRUNC(N34/$R$4,-2) -> 20600 | N34: =$N$9*1.1 -> 165000
E35: =E34+1 -> 30 | G35: Juru Gambar (Drafter) | K35: L.13 | L35: OH | M35: =TRUNC(N35/$R$4,-2) -> 20600 | N35: =$N$9*1.1 -> 165000
E36: =E35+1 -> 31 | G36: Design Engineer | K36: L.15 | L36: OH | M36: =TRUNC(N36/$R$4,-2) -> 20600 | N36: =$N$9*1.1 -> 165000
E37: =E36+1 -> 32 | G37: Operator Printer/Plotter | K37: L.16 | L37: OH | M37: =TRUNC(N37/$R$4,-2) -> 20600 | N37: =$N$9*1.1 -> 165000
E38: =E37+1 -> 33 | G38: Operator crane | K38: L.08 | L38: OH | M38: =TRUNC(N38/$R$4,-2) -> 20600 | N38: =$N$24 -> 165000
E39: =E38+1 -> 34 | G39: Pembantu operator crane | K39: L.09 | L39: OH | M39: =TRUNC(N39/$R$4,-2) -> 18500 | N39: =$N$38*0.9 -> 148500
E40: =E39+1 -> 35 | G40: Bor Master | L40: OH | M40: =TRUNC(N40/$R$4,-2) -> 31200 | N40: 250000
E41: =E40+1 -> 36 | G41: Operator Mesin Bor | L41: OH | M41: =TRUNC(N41/$R$4,-2) -> 11400 | N41: 91700

Sheet HITUNG VOLUME
E2: HITUNG VOLUME PEKERJAAN
Q5: I. PEKERJAAN PERSIAPAN
Q7: 1 | R7: Pembersihan Lahan | S7: p | T7: l | U7: t | V7: Jumlah | W7: Satuan | Y7: Jumlah
R8: Luas Lahan | S8: =I22 -> 20 | T8: =I23 -> 10 | W8: m2 | Y8: =S8*T8 -> 200
Q10: 2 | R10: Pemasangan Bouwplank | S10: p | T10: l | U10: t | V10: Jumlah | W10: Satuan | Y10: Volume
R11: Ukuran bangunan | S11: =N22 -> 8 | T11: =N23 -> 6 | V11: 2 | W11: m2 | Y11: =S11*T11 -> 48
Q13: 3 | R13: Penyediaan Air Kerja | V13: Jumlah | W13: Satuan | Y13: Volume
V14: 1 | W14: Ls | Y14: =V14 -> 1
Q16: 4 | R16: Administrasi & Dokumentasi | V16: Jumlah | W16: Satuan | Y16: Volume
V17: 1 | W17: Ls | Y17: =V17 -> 1
A21: www.rabotomatis.com | F21: Luas Lahan | K21: Luas Bangunan
F22: Panjang | I22: 20 | K22: Panjang | N22: 8
F23: Lebar | I23: 10 | K23: Lebar | N23: 6
Q26: II. PEKERJAAN GALIAN & URUGAN
H27: 1.2
Q28: 1 | R28: Galian Tanah Pondasi | S28: p | T28: lb atas | U28: lb bawah | V28: t | W28: Satuan | Y28: Jumlah
L29: Galian Type 1 | R29: Galian Tanah Type 1 | S29: =L43 -> 22 | T29: =H27 -> 1.2 | U29: =H33 -> 0.9 | V29: =L30 -> 0.65 | W29: m3 | Y29: =(((T29+U29)/2)*V29)*S29 -> 15.015
L30: 0.65 | R30: Galian Tanah Type 2 | S30: =L44 -> 23 | T30: =H35 -> 1.2 | U30: =H41 -> 0.9 | V30: =L38 -> 0.65 | W30: m3 | Y30: =(((T30+U30)/2)*V30)*S30 -> 15.6975
Y31: =SUM(Y29:Y30) -> 30.7125
H33: 0.9
H35: 1.2
L37: Galian Type 2
L38: 0.65
H41: 0.9
F43: Panjang Galian Type 1 | L43: 22
F44: Panjang Galian Type 2 | L44: 23
Q46: 2 | R46: Urugan Tanah Kembali | S46: p | T46: l | U46: t | W46: Satuan | Y46: Jumlah
L47: Urugan Tanah | R47: Urugan Tanah Samping Pondasi (1/4 Galian Tanah) | S47: - | T47: - | U47: - | W47: m3 | Y47: =(Y29+Y30)*0.25 -> 7.678125
L48: Samping Pondasi | R48: Urugan Bawah Lantai | S48: =S11 -> 8 | T48: =T11 -> 6 | U48: =L49 -> 0.4 | W48: m3 | Y48: =S48*T48*U48 -> 19.2
L49: 0.4 | Y49: =SUM(Y47:Y48) -> 26.878125
Q54: 3 | R54: Urugan Pasir Dibawah Pondasi | S54: p | T54: l | U54: t | W54: Satuan | Y54: Jumlah
S55: =S29+S30 -> 45 | T55: =H60 -> 0.9 | U55: =L58 -> 0.05 | W55: m3 | Y55: =S55*T55*U55 -> 2.025
L56: Urugan Pasir
L57: Bawah Pondasi
L58: 0.05
H60: 0.9
Q62: 4 | R62: Urugan Pasir Dibawah Lantai | S62: p | T62: l | U62: t | W62: Satuan | Y62: Jumlah
F63: Tinggi urugan pasir bawah lantai | O63: 0.1 | S63: =S11 -> 8 | T63: =T11 -> 6 | U63: =O63 -> 0.1 | W63: m3 | Y63: =S63*T63*U63 -> 4.8
Q66: III. PEKERJAAN PASANGAN & PLESTERAN
L68: Batu Kosong/ | Q68: 1 | R68: Pasangan Batu Kosong/Aanstamping | S68: p | T68: l | U68: t | W68: Satuan | Y68: Jumlah
...

Sheet HITUNG RAB
E2: HITUNG RAB (Rencana Anggaran Biaya)
E4: No | F4: Item Pekerjaan | G4: Uraian Pekerjaan & Spesifikasi | H4: Kode Analisa | I4: Satuan | J4: Volume | K4: Harga (Rp)
K5: Satuan (Rp) | L5: Jumlah (Rp)
E6: 1 | F6: 2 | G6: 3 | H6: 4 | I6: 5 | J6: 6 | K6: 7 | L6: 8 = 7x6
E7: I | F7: PEKERJAAN PERSIAPAN
E8: 1 | F8: Pembersihan Lahan | G8: Pembersihan 1 m2 dan peralatan lapangan | H8: =IFERROR(INDEX(HSP!$G$7:$G$460,MATCH('HITUNG RAB'!G8,HSP!$H$7:$H$460,0)), "Isi Spesifikasi") -> A.1.1.1.8 | I8: M² | J8: =VLOOKUP(F8,RekapVolume,3,FALSE) -> 200 | K8: =IFERROR(VLOOKUP(H8,HSP!$G$7:$J$460,4,0),"No Data") -> 23100 | L8: =IFERROR(J8*K8, "No Data") -> 4620000
E9: 2 | F9: Pemasangan Bouwplank | G9: Pengukuran dan pemasangan 1 m’ Bouwplank | H9: =IFERROR(INDEX(HSP!$G$7:$G$460,MATCH('HITUNG RAB'!G9,HSP!$H$7:$H$460,0)), "Isi Spesifikasi") -> A.1.1.1.4 | I9: M¹ | J9: =VLOOKUP(F9,RekapVolume,3,FALSE) -> 48 | K9: =IFERROR(VLOOKUP(H9,HSP!$G$7:$J$460,4,0),"No Data") -> 92990 | L9: =IFERROR(J9*K9, "No Data") -> 4463520
E10: 3 | F10: Penyediaan Air Kerja | G10: Langsam | H10: - | I10: LS | J10: =VLOOKUP(F10,RekapVolume,3,FALSE) -> 1 | K10: 500000 | L10: =IFERROR(J10*K10, "No Data") -> 500000
E11: 4 | F11: Administrasi & Dokumentasi | G11: Langsam | H11: - | I11: LS | J11: =VLOOKUP(F11,RekapVolume,3,FALSE) -> 1 | K11: 500000 | L11: =IFERROR(J11*K11, "No Data") -> 500000
K13: Jumlah I | L13: =SUM(L8:L11) -> 10083520
E14: II | F14: PEKERJAAN GALIAN TANAH & URUGAN
E15: 1 | F15: Galian Tanah Pondasi | G15: Penggalian 1 m3 tanah keras sedalam s.d. 1 m | H15: =IFERROR(INDEX(HSP!$G$7:$G$460,MATCH('HITUNG RAB'!G15,HSP!$H$7:$H$460,0)), "Isi Spesifikasi") -> A.1.5.1.4 | I15: M³ | J15: =VLOOKUP(F15,RekapVolume,3,FALSE) -> 30.7125 | K15: =IFERROR(VLOOKUP(H15,HSP!$G$7:$J$460,4,0),"No Data") -> 143484 | L15: =IFERROR(J15*K15, "No Data") -> 4406752.4
E16: 2 | F16: Urugan Tanah Kembali | G16: Pengurugan kembali 1 m3 galian tanah Tanah Biasa Sedalam 1 M | H16: =IFERROR(INDEX(HSP!$G$7:$G$460,MATCH('HITUNG RAB'!G16,HSP!$H$7:$H$460,0)), "Isi Spesifikasi") -> A.1.5.1.9 | I16: M³ | J16: =VLOOKUP(F16,RekapVolume,3,FALSE) -> 26.878125 | K16: =IFERROR(VLOOKUP(H16,HSP!$G$7:$J$460,4,0),"No Data") -> 39050 | L16: =IFERROR(J16*K16, "No Data") -> 1049590.8
E17: 3 | F17: Urugan Pasir Dibawah Pondasi | G17: Pengurugan 1 m3 dengan pasir urug | H17: =IFERROR(INDEX(HSP!$G$7:$G$460,MATCH('HITUNG RAB'!G17,HSP!$H$7:$H$460,0)), "Isi Spesifikasi") -> A.1.5.1.11 | I17: M³ | J17: =VLOOKUP(F17,RekapVolume,3,FALSE) -> 2.025 | K17: =IFERROR(VLOOKUP(H17,HSP!$G$7:$J$460,4,0),"No Data") -> 440426 | L17: =IFERROR(J17*K17, "No Data") -> 891862.65
E18: 4 | F18: Urugan Pasir Dibawah Lantai | G18: Pengurugan 1 m3 dengan pasir urug | H18: =IFERROR(INDEX(HSP!$G$7:$G$460,MATCH('HITUNG RAB'!G18,HSP!$H$7:$H$460,0)), "Isi Spesifikasi") -> A.1.5.1.11 | I18: M³ | J18: =VLOOKUP(F18,RekapVolume,3,FALSE) -> 4.8 | K18: =IFERROR(VLOOKUP(H18,HSP!$G$7:$J$460,4,0),"No Data") -> 440426 | L18: =IFERROR(J18*K18, "No Data") -> 2114044.8
K20: Jumlah II | L20: =SUM(L15:L18) -> 8462250.6
A21: www.rabotomatis.com | E21: III | F21: PEKERJAAN PASANGAN & PLESTERAN
E22: 1 | F22: Pasangan Batu Kosong/Aanstamping | G22: Pemasangan 1 m3 batu kosong (anstamping) | H22: =IFERROR(INDEX(HSP!$G$7:$G$460,MATCH('HITUNG RAB'!G22,HSP!$H$7:$H$460,0)), "Isi Spesifikasi") -> A.3.1.1.9 | I22: M³ | J22: =VLOOKUP(F22,RekapVolume,3,FALSE) -> 6.075 | K22: =IFERROR(VLOOKUP(H22,HSP!$G$7:$J$460,4,0),"No Data") -> 885381 | L22: =IFERROR(J22*K22, "No Data") -> 5378689.6
E23: 2 | F23: Pasangan Pondasi Batu Gunung | G23: Pemasangan 1 m3 pondasi batu belah campuran 1SP : 3PP | H23: =IFERROR(INDEX(HSP!$G$7:$G$460,MATCH('HITUNG RAB'!G23,HSP!$H$7:$H$460,0)), "Isi Spesifikasi") -> A.3.1.1.1 | I23: M³ | J23: =VLOOKUP(F23,RekapVolume,3,FALSE) -> 18 | K23: =IFERROR(VLOOKUP(H23,HSP!$G$7:$J$460,4,0),"No Data") -> 1467001 | L23: =IFERROR(J23*K23, "No Data") -> 26406018
E24: 3 | F24: Pasangan Batu Bata | G24: Pemasangan 1m2 Dinding Bata Merah (5x11x22) cm Tebal ½ Batu dengan Mortar tipe n,fc’ 5,2 Mpa (setara campuran 1 SP : 4 PP) | H24: =IFERROR(INDEX(HSP!$G$7:$G$460,MATCH('HITUNG RAB'!G24,HSP!$H$7:$H$460,0)), "Isi Spesifikasi") -> A.4.4.1.9 | I24: M² | J24: =VLOOKUP(F24,RekapVolume,3,FALSE) -> 72.1 | K24: =IFERROR(VLOOKUP(H24,HSP!$G$7:$J$460,4,0),"No Data") -> 178223 | L24: =IFERROR(J24*K24, "No Data") -> 12849878
E25: 4 | F25: Plesteran Dinding | G25: Pemasangan 1 m2 plesteran 1SP : 5PP tebal 15 mm | H25: =IFERROR(INDEX(HSP!$G$7:$G$460,MATCH('HITUNG RAB'!G25,HSP!$H$7:$H$460,0)), "Isi Spesifikasi") -> A.4.4.2.5 | I25: M² | J25: =VLOOKUP(F25,RekapVolume,3,FALSE) -> 135.23 | K25: =IFERROR(VLOOKUP(H25,HSP!$G$7:$J$460,4,0),"No Data") -> 89498 | L25: =IFERROR(J25*K25, "No Data") -> 12102815
E26: 5 | F26: Acian Dinding | G26: Pemasangan 1 m2 acian. | H26: =IFERROR(INDEX(HSP!$G$7:$G$460,MATCH('HITUNG RAB'!G26,HSP!$H$7:$H$460,0)), "Isi Spesifikasi") -> A.4.4.2.27 | I26: M² | J26: =VLOOKUP(F26,RekapVolume,3,FALSE) -> 135.23 | K26: =IFERROR(VLOOKUP(H26,HSP!$G$7:$J$460,4,0),"No Data") -> 54406 | L26: =IFERROR(J26*K26, "No Data") -> 7357323.4
K28: Jumlah III | L28: =SUM(L22:L26) -> 64094724
E29: IV | F29: PEKERJAAN BETON
E30: 1 | F30: Cor Beton Sloof 20x25 cm
F31: a. Pembesian | G31: Pembesian 10 kg dengan besi polos atau besi ulir | H31: =IFERROR(INDEX(HSP!$G$7:$G$460,MATCH('HITUNG RAB'!G31,HSP!$H$7:$H$460,0)), "Isi Spesifikasi") -> A.4.1.1.18 | I31: Kg | J31: ='REKAP VOLUME'!H27 -> 189.58125 | K31: =VLOOKUP(H31,HSP!$G$7:$J$460,4,0)/10 -> 17691.7 | L31: =IFERROR(J31*K31, "No Data") -> 3354014.6
F32: b. Bekisting | G32: (K3) Pemasangan 1 m2 bekisting untuk sloof beton bangunan gedung | H32: =IFERROR(INDEX(HSP!$G$7:$G$460,MATCH('HITUNG RAB'!G32,HSP!$H$7:$H$460,0)), "Isi Spesifikasi") -> A.4.1.1.22 | I32: M² | J32: ='REKAP VOLUME'!H28 -> 22.5 | K32: =IFERROR(VLOOKUP(H32,HSP!$G$7:$J$460,4,0),"No Data") -> 356765 | L32: =IFERROR(J32*K32, "No Data") -> 8027212.5
F33: c. Beton | G33: Membuat 1 m3 beton mutu f’= 21,7 MPa (K 250), slump (120 ± 20) mm, w/c = 0,56 | H33: =IFERROR(INDEX(HSP!$G$7:$G$460,MATCH('HITUNG RAB'!G33,HSP!$H$7:$H$460,0)), "Isi Spesifikasi") -> A.4.1.1.8 | I33: M³ | J33: ='REKAP VOLUME'!H29 -> 2.25 | K33: =IFERROR(VLOOKUP(H33,HSP!$G$7:$J$460,4,0),"No Data") -> 1802958 | L33: =IFERROR(J33*K33, "No Data") -> 4056655.5
E34: 2 | F34: Cor Kolom Praktis 15x15 cm
F35: a. Pembesian | G35: Pembesian 10 kg dengan besi polos atau besi ulir | H35: =IFERROR(INDEX(HSP!$G$7:$G$460,MATCH('HITUNG RAB'!G35,HSP!$H$7:$H$460,0)), "Isi Spesifikasi") -> A.4.1.1.18 | I35: Kg | J35: ='REKAP VOLUME'!H31 -> 156.42833 | K35: =VLOOKUP(H35,HSP!$G$7:$J$460,4,0)/10 -> 17691.7 | L35: =IFERROR(J35*K35, "No Data") -> 2767483.1
F36: b. Bekisting | G36: (K3) Pemasangan 1 m2 bekisting untuk kolom beton bangunan gedung | H36: =IFERROR(INDEX(HSP!$G$7:$G$460,MATCH('HITUNG RAB'!G36,HSP!$H$7:$H$460,0)), "Isi Spesifikasi") -> A.4.1.1.23 | I36: M² | J36: ='REKAP VOLUME'!H32 -> 20.4 | K36: =IFERROR(VLOOKUP(H36,HSP!$G$7:$J$460,4,0),"No Data") -> 562765 | L36: =IFERROR(J36*K36, "No Data") -> 11480406
F37: c. Beton | G37: Membuat 1 m3 beton mutu f’= 21,7 MPa (K 250), slump (120 ± 20) mm, w/c = 0,56 | H37: =IFERROR(INDEX(HSP!$G$7:$G$460,MATCH('HITUNG RAB'!G37,HSP!$H$7:$H$460,0)), "Isi Spesifikasi") -> A.4.1.1.8 | I37: M³ | J37: ='REKAP VOLUME'!H33 -> 1.53 | K37: =IFERROR(VLOOKUP(H37,HSP!$G$7:$J$460,4,0),"No Data") -> 1802958 | L37: =IFERROR(J37*K37, "No Data") -> 2758525.7
E38: 3 | F38: Cor Ring Balk 15x15 cm
F39: a. Pembesian | G39: Pembesian 10 kg dengan besi polos atau besi ulir | H39: =IFERROR(INDEX(HSP!$G$7:$G$460,MATCH('HITUNG RAB'!G39,HSP!$H$7:$H$460,0)), "Isi Spesifikasi") -> A.4.1.1.18 | I39: Kg | J39: ='REKAP VOLUME'!H35 -> 103.51875 | K39: =VLOOKUP(H39,HSP!$G$7:$J$460,4,0)/10 -> 17691.7 | L39: =IFERROR(J39*K39, "No Data") -> 1831422.7
F40: b. Bekisting | G40: (K3) Pemasangan 1 m2 bekisting untuk balok beton bangunan gedung | H40: =IFERROR(INDEX(HSP!$G$7:$G$460,MATCH('HITUNG RAB'!G40,HSP!$H$7:$H$460,0)), "Isi Spesifikasi") -> A.4.1.1.24 | I40: M² | J40: ='REKAP VOLUME'!H36 -> 13.5 | K40: =IFERROR(VLOOKUP(H40,HSP!$G$7:$J$460,4,0),"No Data") -> 577318 | L40: =IFERROR(J40*K40, "No Data") -> 7793793
F41: c. Beton | G41: Membuat 1 m3 beton mutu f’= 21,7 MPa (K 250), slump (120 ± 20) mm, w/c = 0,56 | H41: =IFERROR(INDEX(HSP!$G$7:$G$460,MATCH('HITUNG RAB'!G41,HSP!$H$7:$H$460,0)), "Isi Spesifikasi") -> A.4.1.1.8 | I41: M³ | J41: ='REKAP VOLUME'!H37 -> 1.0125 | K41: =IFERROR(VLOOKUP(H41,HSP!$G$7:$J$460,4,0),"No Data") -> 1802958 | L41: =IFERROR(J41*K41, "No Data") -> 1825495
E42: 4 | F42: Cor Teras Depan
F43: a. Pembesian | G43: Pembesian 10 kg dengan besi polos atau besi ulir | H43: =IFERROR(INDEX(HSP!$G$7:$G$460,MATCH('HITUNG RAB'!G43,HSP!$H$7:$H$460,0)), "Isi Spesifikasi") -> A.4.1.1.18 | I43: Kg | J43: ='REKAP VOLUME'!H39 -> 37 | K43: =VLOOKUP(H43,HSP!$G$7:$J$460,4,0)/10 -> 17691.7 | L43: =IFERROR(J43*K43, "No Data") -> 654592.9
F44: b. Bekisting | G44: (K3) Pemasangan 1 m2 bekisting untuk plat lantai beton bangunan gedung | H44: =IFERROR(INDEX(HSP!$G$7:$G$460,MATCH('HITUNG RAB'!G44,HSP!$H$7:$H$460,0)), "Isi Spesifikasi") -> A.4.1.1.25 | I44: M² | J44: ='REKAP VOLUME'!H40 -> 3 | K44: =IFERROR(VLOOKUP(H44,HSP!$G$7:$J$460,4,0),"No Data") -> 700265 | L44: =IFERROR(J44*K44, "No Data") -> 2100795
F45: c. Beton | G45: Membuat 1 m3 beton mutu f’= 21,7 MPa (K 250), slump (120 ± 20) mm, w/c = 0,56 | H45: =IFERROR(INDEX(HSP!$G$7:$G$460,MATCH('HITUNG RAB'!G45,HSP!$H$7:$H$460,0)), "Isi Spesifikasi") -> A.4.1.1.8 | I45: M³ | J45: ='REKAP VOLUME'!H41 -> 0.36 | K45: =IFERROR(VLOOKUP(H45,HSP!$G$7:$J$460,4,0),"No Data") -> 1802958 | L45: =IFERROR(J45*K45, "No Data") -> 649064.88
...

Sheet REKAPITULASI
E2: REKAPITULASI
A36: www.rabotomatis.com

Sheet REKAP VOLUME
E2: REKAP VOLUME PEKERJAAN
E4: No | F4: Uraian Pekerjaan | G4: Satuan | H4: Volume
E5: 1 | F5: 2 | G5: 3 | H5: 4
E6: I | F6: PEKERJAAN PERSIAPAN
E7: 1 | F7: Pembersihan Lahan | G7: M² | H7: ='HITUNG VOLUME'!Y8 -> 200
E8: 2 | F8: Pemasangan Bouwplank | G8: M¹ | H8: ='HITUNG VOLUME'!Y11 -> 48
E9: 3 | F9: Penyediaan Air Kerja | G9: LS | H9: ='HITUNG VOLUME'!Y14 -> 1
E10: 4 | F10: Administrasi & Dokumentasi | G10: LS | H10: ='HITUNG VOLUME'!Y17 -> 1
E12: II | F12: PEKERJAAN GALIAN TANAH & URUGAN
E13: 1 | F13: Galian Tanah Pondasi | G13: M³ | H13: ='HITUNG VOLUME'!Y31 -> 30.7125
E14: 2 | F14: Urugan Tanah Kembali | G14: M³ | H14: ='HITUNG VOLUME'!Y49 -> 26.878125
E15: 3 | F15: Urugan Pasir Dibawah Pondasi | G15: M³ | H15: ='HITUNG VOLUME'!Y55 -> 2.025
E16: 4 | F16: Urugan Pasir Dibawah Lantai | G16: M³ | H16: ='HITUNG VOLUME'!Y63 -> 4.8
E18: III | F18: PEKERJAAN PASANGAN DAN PLESTERAN
E19: 1 | F19: Pasangan Batu Kosong/Aanstamping | G19: M³ | H19: ='HITUNG VOLUME'!Y70 -> 6.075
E20: 2 | F20: Pasangan Pondasi Batu Gunung | G20: M³ | H20: ='HITUNG VOLUME'!Y78 -> 18
E21: 3 | F21: Pasangan Batu Bata | G21: M² | H21: ='HITUNG VOLUME'!Y101 -> 72.1
E22: 4 | F22: Plesteran Dinding | G22: M² | H22: ='HITUNG VOLUME'!Y106 -> 135.23
E23: 5 | F23: Acian Dinding | G23: M² | H23: ='HITUNG VOLUME'!Y111 -> 135.23
E25: IV | F25: PEKERJAAN BETON
E26: 1 | F26: Cor Beton Sloof 20x25 cm
F27: a. Pembesian | G27: Kg | H27: ='HITUNG VOLUME'!Y138 -> 189.58125
F28: b. Bekisting | G28: M² | H28: ='HITUNG VOLUME'!Y141 -> 22.5
F29: c. Beton | G29: M³ | H29: ='HITUNG VOLUME'!Y144 -> 2.25
E30: 2 | F30: Cor Kolom Praktis 15x15 cm
F31: a. Pembesian | G31: Kg | H31: ='HITUNG VOLUME'!Y162 -> 156.42833
F32: b. Bekisting | G32: M² | H32: ='HITUNG VOLUME'!Y165 -> 20.4
F33: c. Beton | G33: M³ | H33: ='HITUNG VOLUME'!Y168 -> 1.53
E34: 3 | F34: Cor Ring Balk 15x15 cm
A35: www.rabotomatis.com | F35: a. Pembesian | G35: Kg | H35: ='HITUNG VOLUME'!Y186 -> 103.51875
F36: b. Bekisting | G36: M² | H36: ='HITUNG VOLUME'!Y189 -> 13.5
F37: c. Beton | G37: M³ | H37: ='HITUNG VOLUME'!Y192 -> 1.0125
E38: 4 | F38: Cor Teras Depan
F39: a. Pembesian | G39: Kg | H39: ='HITUNG VOLUME'!Y203 -> 37
F40: b. Bekisting | G40: M² | H40: ='HITUNG VOLUME'!Y206 -> 3
F41: c. Beton | G41: M³ | H41: ='HITUNG VOLUME'!Y209 -> 0.36
E42: 5 | F42: Cor Teras Belakang
F43: a. Pembesian | G43: Kg | H43: ='HITUNG VOLUME'!Y225 -> 34.533333
F44: b. Bekisting | G44: M² | H44: ='HITUNG VOLUME'!Y228 -> 2.8
F45: c. Beton | G45: M³ | H45: ='HITUNG VOLUME'!Y231 -> 0.336
...

Sheet REKAP RAB
E2: REKAP RAB
E4: No | F4: Uraian Pekerjaan | J4: Jumlah (Rp)
E6: 1 | F6: 2 | J6: 3
E7: I | F7: PEKERJAAN PERSIAPAN | J7: ='HITUNG RAB'!L13 -> 10083520
E8: II | F8: PEKERJAAN GALIAN TANAH & URUGAN | J8: ='HITUNG RAB'!L20 -> 8462250.6
E9: III | F9: PEKERJAAN PASANGAN & PLESTERAN | J9: ='HITUNG RAB'!L28 -> 64094724
E10: IV | F10: PEKERJAAN BETON | J10: ='HITUNG RAB'!L51 -> 50476950
E11: V | F11: PEKERJAAN ATAP & PLAFOND | J11: ='HITUNG RAB'!L60 -> 94737640
E12: VI | F12: PEKERJAAN KUSEN PINTU & JENDELA | J12: ='HITUNG RAB'!L68 -> 13388297
E13: VII | F13: PEKERJAAN LANTAI & KERAMIK | J13: ='HITUNG RAB'!L73 -> 14415840
E14: VIII | F14: PEKERJAAN PENGGANTUNG & PENGUNCI | J14: ='HITUNG RAB'!L83 -> 3675048
E15: IX | F15: PEKERJAAN INSTALASI LISTRIK & AIR | J15: ='HITUNG RAB'!L98 -> 8180192
E16: X | F16: PEKERJAAN FINISHING | J16: ='HITUNG RAB'!L105 -> 9424125.6
E17: XI | F17: PEKERJAAN SEPTITANK & PERESAPAN | J17: ='HITUNG RAB'!L124 -> 29017311
E18: XII | F18: PEKERJAAN LAIN-LAIN | J18: ='HITUNG RAB'!L128 -> 1540000
I19: Jumlah | J19: =SUM(J7:J18) -> 3.074959e+08
A31: www.rabotomatis.com

Sheet REKAP PEKERJA
E2: REKAP PEKERJA
E5: No | F5: Uraian Pekerjaan | H5: Koef Tenaga Kerja | I5: Kemampuan Pekerja | J5: Vol Pek | K5: Jumlah Hari Untuk | L5: Rencana | M5: Jumlah Org Yang | P5: URAIAN PEKERJAAN | Q5: Jumlah | R5: WAKTU PELAKSANAAN (HARI)
H6: Per Satuan Pekerjaan | I6: Menyelesaikan Pkrjn | K6: Menyelesaikan Kes Vol Pek | L6: Hari Kerja | M6: Dibutuhkan | Q6: Hari | R6: 1 | S6: 2 | T6: 3 | U6: 4 | V6: 5 | W6: 6 | X6: 7 | Y6: 8 | Z6: 9 | AA6: 10 | AB6: 11 | AC6: 12 | AD6: 13 | AE6: 14 | AF6: 15 | AG6: 16 | AH6: 17 | AI6: 18 | AJ6: 19 | AK6: 20 | AL6: 21 | AM6: 22 | AN6: 23 | AO6: 24 | AP6: 25 | AQ6: 26 | AR6: 27 | AS6: 28 | AT6: 29 | AU6: 30 | AV6: 31 | AW6: 32 | AX6: 33 | AY6: 34 | AZ6: 35 | BA6: 36 | BB6: 37 | BC6: 38 | BD6: 39 | BE6: 40 | BF6: 41 | BG6: 42 | BH6: 43 | BI6: 44 | BJ6: 45 | BK6: 46 | BL6: 47 | BM6: 48 | BN6: 49 | BO6: 50 | BP6: 51 | BQ6: 52 | BR6: 53 | BS6: 54 | BT6: 55 | BU6: 56 | BV6: 57 | BW6: 58 | BX6: 59 | BY6: 60 | BZ6: 61 | CA6: 62 | CB6: 63 | CC6: 64 | CD6: 65 | CE6: 66 | CF6: 67 | CG6: 68 | CH6: 69 | CI6: 70 | CJ6: 71 | CK6: 72 | CL6: 73 | CM6: 74 | CN6: 75 | CO6: 76 | CP6: 77 | CQ6: 78 | CR6: 79 | CS6: 80 | CT6: 81 | CU6: 82 | CV6: 83 | CW6: 84 | CX6: 85 | CY6: 86 | CZ6: 87 | DA6: 88 | DB6: 89 | DC6: 90 | DD6: 91 | DE6: 92 | DF6: 93 | DG6: 94 | DH6: 95 | DI6: 96 | DJ6: 97 | DK6: 98 | DL6: 99 | DM6: 100 | DN6: 101 | DO6: 102 | DP6: 103 | DQ6: 104 | DR6: 105 | DS6: 106 | DT6: 107 | DU6: 108 | DV6: 109 | DW6: 110 | DX6: 111 | DY6: 112 | DZ6: 113 | EA6: 114 | EB6: 115 | EC6: 116 | ED6: 117 | EE6: 118 | EF6: 119 | EG6: 120 | EH6: 121 | EI6: 122 | EJ6: 123 | EK6: 124 | EL6: 125 | EM6: 126 | EN6: 127 | EO6: 128 | EP6: 129 | EQ6: 130 | ER6: 131 | ES6: 132 | ET6: 133 | EU6: 134 | EV6: 135 | EW6: 136 | EX6: 137 | EY6: 138 | EZ6: 139 | FA6: 140 | FB6: 141 | FC6: 142 | FD6: 143 | FE6: 144 | FF6: 145 | FG6: 146 | FH6: 147 | FI6: 148 | FJ6: 149 | FK6: 150 | FL6: 151 | FM6: 152 | FN6: 153 | FO6: 154 | FP6: 155 | FQ6: 156 | FR6: 157 | FS6: 158 | FT6: 159 | FU6: 160 | FV6: 161 | FW6: 162 | FX6: 163 | FY6: 164 | FZ6: 165 | GA6: 166 | GB6: 167 | GC6: 168 | GD6: 169 | GE6: 170 | GF6: 171 | GG6: 172 | GH6: 173 | GI6: 174 | GJ6: 175 | GK6: 176 | GL6: 177 | GM6: 178 | GN6: 179 | GO6: 180 | GP6: 181 | GQ6: 182 | GR6: 183 | GS6: 184 | GT6: 185 | GU6: 186 | GV6: 187 | GW6: 188 | GX6: 189 | GY6: 190
H7: (a) | I7: Dalam 1 Hari (b) | J7: ( c ) | K7: (1 Org) (d) | L7: (e) | M7: (f) | N7: (g) | P7: PEKERJAAN PERSIAPAN
I8: 1/a | K8: c/b | M8: d/e | P8: Pembersihan Lapangan
F9: PEKERJAAN PERSIAPAN | P9: Pasangan Bouwlpank
F10: 1 M2 Pembersihan Lapangan | G10: P | H10: =AHSP!J174 -> 0.1 | I10: =1/H10 -> 10 | J10: ='REKAP VOLUME'!H7 -> 200 | K10: =J10/I10 -> 20 | L10: 4 | M10: =K10/L10 -> 5 | N10: =M10 -> 5 | P10: Gudang Semen dan Alat
G11: M | H11: =AHSP!J175 -> 0.05 | I11: =1/H11 -> 20 | J11: ='REKAP VOLUME'!H7 -> 200 | K11: =J11/I11 -> 10 | L11: 4 | M11: =K11/L11 -> 2.5 | N11: =M11 -> 2.5 | P11: PEKERJAAN GALIAN
P12: Galian Tanah
F13: 1 M' Pasangan Bouwlpank | G13: P | H13: =AHSP!J80 -> 0.1 | I13: =1/H13 -> 10 | J13: ='REKAP VOLUME'!H8 -> 48 | K13: =J13/I13 -> 4.8 | L13: 2 | M13: =K13/L13 -> 2.4 | N13: =M13 -> 2.4 | P13: Urugan Kembali Galian Tanah
G14: T | H14: =AHSP!J81 -> 0.1 | I14: =1/H14 -> 10 | J14: =J13 -> 48 | K14: =J14/I14 -> 4.8 | L14: 2 | M14: =K14/L14 -> 2.4 | N14: =M14 -> 2.4 | P14: PEK. PONDASI BATU KALI
G15: KT | H15: =AHSP!J82 -> 0.01 | I15: =1/H15 -> 100 | J15: =J14 -> 48 | K15: =J15/I15 -> 0.48 | L15: 2 | M15: =K15/L15 -> 0.24 | N15: 1 | P15: Urugan Pasir Bawah Pondasi
G16: M | H16: =AHSP!J83 -> 0.005 | I16: =1/H16 -> 200 | J16: =J15 -> 48 | K16: =J16/I16 -> 0.24 | L16: 2 | M16: =K16/L16 -> 0.12 | N16: 1 | P16: Pasangan Pondasi Batu Kosong
P17: Pasangan Pondasi Batu Kali (1:3)
F18: 1 M2 Gudang Semen dan Alat | G18: P | H18: 2 | I18: =1/H18 -> 0.5 | J18: 1 | K18: =J18/I18 -> 2 | L18: 3 | M18: =K18/L18 -> 0.66666667 | N18: =M18 -> 0.66666667 | P18: PEK. BETON
G19: T | H19: 1 | I19: =1/H19 -> 1 | J19: 1 | K19: =J19/I19 -> 1 | L19: 3 | M19: =K19/L19 -> 0.33333333 | N19: =M19 -> 0.33333333 | P19: Pondasi Plat
G20: KT | H20: 0.2 | I20: =1/H20 -> 5 | J20: 1 | K20: =J20/I20 -> 0.2 | L20: 3 | M20: =K20/L20 -> 0.066666667 | N20: =M20 -> 0.066666667
G21: M | H21: 0.05 | I21: =1/H21 -> 20 | J21: 1 | K21: =J21/I21 -> 0.05 | L21: 3 | M21: =K21/L21 -> 0.016666667 | N21: =M21 -> 0.016666667 | P21: Kolom
F22: PEKERJAAN GALIAN | P22: Balok
F23: 1 M3 Galian Tanah Biasa Sedalam 1 Meter | G23: P | H23: =AHSP!J332 -> 0.75 | I23: =1/H23 -> 1.3333333 | J23: ='REKAP VOLUME'!H13 -> 30.7125 | K23: =J23/I23 -> 23.034375 | L23: 7 | M23: =K23/L23 -> 3.290625 | N23: =M23 -> 3.290625 | P23: Plat Beton
G24: M | H24: =AHSP!J333 -> 0.025 | I24: =1/H24 -> 40 | J24: =J23 -> 30.7125 | K24: =J24/I24 -> 0.7678125 | L24: 7 | M24: =K24/L24 -> 0.1096875 | N24: =M24 -> 0.1096875 | P24: Ring Balok
P25: Tangga Beton Bertulang
F26: 1 M3 Galian Tanah Biasa Sedalam 2 Meter | G26: P | H26: =AHSP!J346 -> 0.9 | I26: =1/H26 -> 1.1111111 | J26: 0 | K26: =J26/I26 -> 0 | L26: 0 | M26: =K26/L26 -> #DIV/0! | N26: =M26 -> #DIV/0! | P26: PEK. DINDING
G27: M | H27: =AHSP!J347 -> 0.045 | I27: =1/H27 -> 22.222222 | J27: 0 | K27: =J27/I27 -> 0 | L27: 0 | M27: =K27/L27 -> #DIV/0! | N27: =M27 -> #DIV/0! | P27: Pasangan Dinding Batu Bata (1:4)
P28: Pasangan Dinding Batu Bata (1:2)
F29: 1 M3 Galian Tanah Biasa Sedalam 3 Meter | G29: P | H29: =AHSP!J360 -> 1.05 | I29: =1/H29 -> 0.95238095 | J29: 0 | K29: =J29/I29 -> 0 | L29: 0 | M29: =K29/L29 -> #DIV/0! | N29: =M29 -> #DIV/0! | P29: Pasangan Kusen Pintu dan Jendela
G30: M | H30: =AHSP!J361 -> 0.067 | I30: =1/H30 -> 14.925373 | J30: 0 | K30: =J30/I30 -> 0 | L30: 0 | M30: =K30/L30 -> #DIV/0! | N30: =M30 -> #DIV/0! | P30: PEK. KAP DAN ATAP
P31: Pekerjaan Balok Dinding
F32: 1 M3 Galian Tanah Keras Sedalam 1 Meter | G32: P | H32: =AHSP!J374 -> 1 | I32: =1/H32 -> 1 | J32: 0 | K32: =J32/I32 -> 0 | L32: 0 | M32: =K32/L32 -> #DIV/0! | N32: =M32 -> #DIV/0! | P32: Pekerjaan Kuda-Kuda Kayu
G33: M | H33: =AHSP!J375 -> 0.032 | I33: =1/H33 -> 31.25 | J33: 0 | K33: =J33/I33 -> 0 | L33: 0 | M33: =K33/L33 -> #DIV/0! | N33: =M33 -> #DIV/0! | P33: Pekerjaan rangka Atap
P34: Papan Lisplank
A35: www.rabotomatis.com | F35: 1 M3 Galian Tanah Cadas Sedalam 1 Meter | G35: P | H35: =AHSP!J388 -> 1.5 | I35: =1/H35 -> 0.66666667 | J35: 0 | K35: =J35/I35 -> 0 | L35: 0 | M35: =K35/L35 -> #DIV/0! | N35: =M35 -> #DIV/0! | P35: Pemasangan Gording, Nog
G36: M | H36: =AHSP!J389 -> 0.06 | I36: =1/H36 -> 16.666667 | J36: 0 | K36: =J36/I36 -> 0 | L36: 0 | M36: =K36/L36 -> #DIV/0! | N36: =M36 -> #DIV/0! | P36: Pemasangan Talang
P37: Pemasangan Atap Sakura Roof
F38: 1 M3 Galian Tanah Lumpur Sedalam 1 Meter | G38: P | H38: =AHSP!J402 -> 1.2 | I38: =1/H38 -> 0.83333333 | J38: 0 | K38: =J38/I38 -> 0 | L38: 0 | M38: =K38/L38 -> #DIV/0! | N38: =M38 -> #DIV/0! | P38: Pemasangan Perabung
G39: M | H39: =AHSP!J403 -> 0.045 | I39: =1/H39 -> 22.222222 | J39: 0 | K39: =J39/I39 -> 0 | L39: 0 | M39: =K39/L39 -> #DIV/0! | N39: =M39 -> #DIV/0! | P39: PEKERJAAN PLAFON
P40: Rangka Plafon
F41: 1 M3 Urugan Kembali Galian Tanah | G41: P | H41: =AHSP!J445 -> 0.25 | I41: =1/H41 -> 4 | J41: ='REKAP VOLUME'!H14 -> 26.878125 | K41: =J41/I41 -> 6.7195313 | L41: 2 | M41: =K41/L41 -> 3.3597656 | N41: =M41 -> 3.3597656 | P41: Plafond Gypsum
G42: M | H42: =AHSP!J446 -> 0.025 | I42: =1/H42 -> 40 | J42: =J41 -> 26.878125 | K42: =J42/I42 -> 0.67195313 | L42: 2 | M42: =K42/L42 -> 0.33597656 | N42: 1 | P42: Memasang Lis Plafond
P43: PEKERJAAN PLASTERAN
...

Sheet PERH. TULANGAN
E2: PERITUNGAN TULANGAN
E4: No. | F4: Tipe konstruksi | G4: Panjang Ekivalen=1m3 | J4: Kebutuhan Tul. | M4: Brt Tul | N4: Berat per | O4: Kebutuhan | P4: Panjang | Q4: Luasan | R4: Jumlah Begel
G5: lbr | H5: tg | I5: panj | J5: (mm) | M5: (Kg/m') | N5: 1m' (kg) | O5: per m3 (kg) | P5: Per M3 | Q5: Bekisting (m2)
E6: A. | F6: Tulangan Pokok
E7: 1 | F7: Balok sloof 15 x 20 | G7: 0.15 | H7: 0.2 | I7: =1/(G7*H7) -> 33.333333 | J7: 4 | K7: Ø | L7: 10 | M7: =VLOOKUP(L7,$E$64:$F$71,2,0) -> 0.617 | N7: =J7*M7 -> 2.468 | O7: =I7*N7 -> 82.266667 | P7: =k_tlg_sloof_d10/(M7*12) -> 11.111111 | Q7: =2*(H7)*I7 -> 13.333333 | R7: =(1/(G7*H7))/0.2 -> 166.66667 | S7: 167
E8: 2 | F8: Kolom 15 x 15 | G8: 0.15 | H8: 0.15 | I8: =1/(G8*H8) -> 44.444444 | J8: 4 | K8: Ø | L8: 10 | M8: =VLOOKUP(L8,$E$64:$F$71,2,0) -> 0.617 | N8: =J8*M8 -> 2.468 | O8: =I8*N8 -> 109.68889 | P8: =k_tlg_kolom_1515/(M7*12) -> 14.814815 | Q8: =(2*G8+H8)*I8 -> 20 | R8: =(1/(G8*H8))/0.2 -> 222.22222 | S8: 223
E9: 3 | F9: Kolom 15 x 20 | G9: 0.15 | H9: 0.2 | I9: =1/(G9*H9) -> 33.333333 | J9: 4 | K9: Ø | L9: 10 | M9: =VLOOKUP(L9,$E$64:$F$71,2,0) -> 0.617 | N9: =J9*M9 -> 2.468 | O9: =I9*N9 -> 82.266667 | P9: =O9/(M9*12) -> 11.111111 | Q9: =(2*G9+H9)*I9 -> 16.666667 | R9: =(1/(G9*H9))/0.2 -> 166.66667 | S9: 167
E10: 4 | F10: Kolom 15 x 25 | G10: 0.15 | H10: 0.25 | I10: =1/(G10*H10) -> 26.666667 | J10: 4 | K10: Ø | L10: 10 | M10: =VLOOKUP(L10,$E$64:$F$71,2,0) -> 0.617 | N10: =J10*M10 -> 2.468 | O10: =I10*N10 -> 65.813333 | P10: =O10/(M10*12) -> 8.8888889 | Q10: =(2*G10+H10)*I10 -> 14.666667 | R10: =(1/(G10*H10))/0.2 -> 133.33333 | S10: 134
E11: 5 | F11: Kolom 15 x 30 | G11: 0.15 | H11: 0.3 | I11: =1/(G11*H11) -> 22.222222 | J11: 6 | K11: Ø | L11: 10 | M11: =VLOOKUP(L11,$E$64:$F$71,2,0) -> 0.617 | N11: =J11*M11 -> 3.702 | O11: =I11*N11 -> 82.266667 | P11: =O11/(M11*12) -> 11.111111 | Q11: =(2*G11+H11)*I11 -> 13.333333 | R11: =(1/(G11*H11))/0.2 -> 111.11111 | S11: 112
E12: 6 | F12: Kolom 20 x 20 | G12: 0.2 | H12: 0.2 | I12: =1/(G12*H12) -> 25 | J12: 4 | K12: Ø | L12: 10 | M12: =VLOOKUP(L12,$E$64:$F$71,2,0) -> 0.617 | N12: =J12*M12 -> 2.468 | O12: =I12*N12 -> 61.7 | P12: =O12/(M12*12) -> 8.3333333 | Q12: =(2*G12+H12)*I12 -> 15 | R12: =(1/(G12*H12))/0.2 -> 125 | S12: 125
E13: 7 | F13: Kolom 20 x 25 | G13: 0.2 | H13: 0.25 | I13: =1/(G13*H13) -> 20 | J13: 4 | K13: Ø | L13: 6 | M13: =VLOOKUP(L13,$E$64:$F$71,2,0) -> 0.222 | N13: =J13*M13 -> 0.888 | O13: =I13*N13 -> 17.76 | P13: =O13/(M13*12) -> 6.6666667 | Q13: =(2*G13+H13)*I13 -> 13 | R13: =(1/(G13*H13))/0.2 -> 100 | S13: 100
E14: 8 | F14: Kolom 20 x 30 | G14: 0.2 | H14: 0.3 | I14: =1/(G14*H14) -> 16.666667 | J14: 6 | K14: Ø | L14: 12 | M14: =VLOOKUP(L14,$E$64:$F$71,2,0) -> 0.888 | N14: =J14*M14 -> 5.328 | O14: =I14*N14 -> 88.8 | P14: =O14/(M14*12) -> 8.3333333 | Q14: =(2*G14+H14)*I14 -> 11.666667 | R14: =(1/(G14*H14))/0.2 -> 83.333333 | S14: 84
E15: 9 | F15: Kolom 20 x 35 | G15: 0.2 | H15: 0.35 | I15: =1/(G15*H15) -> 14.285714 | J15: 1 | K15: Ø | L15: 6 | M15: =VLOOKUP(L15,$E$64:$F$71,2,0) -> 0.222 | N15: =J15*M15 -> 0.222 | O15: =I15*N15 -> 3.1714286 | P15: =O15/(M15*12) -> 1.1904762 | Q15: =(2*G15+H15)*I15 -> 10.714286 | R15: =(1/(G15*H15))/0.2 -> 71.428571 | S15: 72
E16: 10 | F16: Kolom 20 x 40 | G16: 0.2 | H16: 0.4 | I16: =1/(G16*H16) -> 12.5 | J16: 1 | K16: Ø | L16: 6 | M16: =VLOOKUP(L16,$E$64:$F$71,2,0) -> 0.222 | N16: =J16*M16 -> 0.222 | O16: =I16*N16 -> 2.775 | P16: =O16/(M16*12) -> 1.0416667 | Q16: =(2*G16+H16)*I16 -> 10 | R16: =(1/(G16*H16))/0.2 -> 62.5 | S16: 63
E17: 11 | F17: Kolom 25 x 25 | G17: 0.25 | H17: 0.25 | I17: =1/(G17*H17) -> 16 | J17: 1 | K17: Ø | L17: 6 | M17: =VLOOKUP(L17,$E$64:$F$71,2,0) -> 0.222 | N17: =J17*M17 -> 0.222 | O17: =I17*N17 -> 3.552 | P17: =O17/(M17*12) -> 1.3333333 | Q17: =(2*G17+H17)*I17 -> 12 | R17: =(1/(G17*H17))/0.2 -> 80 | S17: 80
E18: 12 | F18: Kolom 25 x 30 | G18: 0.25 | H18: 0.3 | I18: =1/(G18*H18) -> 13.333333 | J18: 1 | K18: Ø | L18: 12 | M18: =VLOOKUP(L18,$E$64:$F$71,2,0) -> 0.888 | N18: =J18*M18 -> 0.888 | O18: =I18*N18 -> 11.84 | P18: =O18/(M18*12) -> 1.1111111 | Q18: =(2*G18+H18)*I18 -> 10.666667 | R18: =(1/(G18*H18))/0.2 -> 66.666667 | S18: 67
E19: 13 | F19: Kolom 25 x 35 | G19: 0.25 | H19: 0.35 | I19: =1/(G19*H19) -> 11.428571 | J19: 1 | K19: Ø | L19: 6 | M19: =VLOOKUP(L19,$E$64:$F$71,2,0) -> 0.222 | N19: =J19*M19 -> 0.222 | O19: =I19*N19 -> 2.5371429 | P19: =O19/(M19*12) -> 0.95238095 | Q19: =(2*G19+H19)*I19 -> 9.7142857 | R19: =(1/(G19*H19))/0.2 -> 57.142857 | S19: 58
E20: 14 | F20: Kolom 25 x 40 | G20: 0.25 | H20: 0.4 | I20: =1/(G20*H20) -> 10 | J20: 1 | K20: Ø | L20: 6 | M20: =VLOOKUP(L20,$E$64:$F$71,2,0) -> 0.222 | N20: =J20*M20 -> 0.222 | O20: =I20*N20 -> 2.22 | P20: =O20/(M20*12) -> 0.83333333 | Q20: =(2*G20+H20)*I20 -> 9 | R20: =(1/(G20*H20))/0.2 -> 50 | S20: 50
... E34: 28 | F34: Balok 20 x 20 | G34: 0.2 | H34: 0.2 | I34: =1/(G34*H34) -> 25 | J34: 1 | K34: Ø | L34: 6 | M34: =VLOOKUP(L34,$E$64:$F$71,2,0) -> 0.222 | N34: =J34*M34 -> 0.222 | O34: =I34*N34 -> 5.55 | P34: =O34/(M34*12) -> 2.0833333 | Q34: =(2*G34+H34)*I34 -> 15 | R34: =(1/(G34*H34))/0.2 -> 125 | S34: 125
A35: www.rabotomatis.com | E35: 29 | F35: Balok 20 x 25 | G35: 0.2 | H35: 0.25 | I35: =1/(G35*H35) -> 20 | J35: 1 | K35: Ø | L35: 6 | M35: =VLOOKUP(L35,$E$64:$F$71,2,0) -> 0.222 | N35: =J35*M35 -> 0.222 | O35: =I35*N35 -> 4.44 | P35: =O35/(M35*12) -> 1.6666667 | Q35: =(2*G35+H35)*I35 -> 13 | R35: =(1/(G35*H35))/0.2 -> 100 | S35: 100
E36: 30 | F36: Balok 20 x 30 | G36: 0.2 | H36: 0.3 | I36: =1/(G36*H36) -> 16.666667 | J36: 1 | K36: Ø | L36: 6 | M36: =VLOOKUP(L36,$E$64:$F$71,2,0) -> 0.222 | N36: =J36*M36 -> 0.222 | O36: =I36*N36 -> 3.7 | P36: =O36/(M36*12) -> 1.3888889 | Q36: =(2*G36+H36)*I36 -> 11.666667 | R36: =(1/(G36*H36))/0.2 -> 83.333333 | S36: 84
E37: 31 | F37: Balok 20 x 35 | G37: 0.2 | H37: 0.35 | I37: =1/(G37*H37) -> 14.285714 | J37: 1 | K37: Ø | L37: 6 | M37: =VLOOKUP(L37,$E$64:$F$71,2,0) -> 0.222 | N37: =J37*M37 -> 0.222 | O37: =I37*N37 -> 3.1714286 | P37: =O37/(M37*12) -> 1.1904762 | Q37: =(2*G37+H37)*I37 -> 10.714286 | R37: =(1/(G37*H37))/0.2 -> 71.428571 | S37: 72
E38: 32 | F38: Balok 20 x 40 | G38: 0.2 | H38: 0.4 | I38: =1/(G38*H38) -> 12.5 | J38: 1 | K38: Ø | L38: 6 | M38: =VLOOKUP(L38,$E$64:$F$71,2,0) -> 0.222 | N38: =J38*M38 -> 0.222 | O38: =I38*N38 -> 2.775 | P38: =O38/(M38*12) -> 1.0416667 | Q38: =(2*G38+H38)*I38 -> 10 | R38: =(1/(G38*H38))/0.2 -> 62.5 | S38: 63
E39: 33 | F39: Balok 25 x 25 | G39: 0.25 | H39: 0.25 | I39: =1/(G39*H39) -> 16 | J39: 1 | K39: Ø | L39: 6 | M39: =VLOOKUP(L39,$E$64:$F$71,2,0) -> 0.222 | N39: =J39*M39 -> 0.222 | O39: =I39*N39 -> 3.552 | P39: =O39/(M39*12) -> 1.3333333 | Q39: =(2*G39+H39)*I39 -> 12 | R39: =(1/(G39*H39))/0.2 -> 80 | S39: 80
E40: 34 | F40: Balok 25 x 30 | G40: 0.25 | H40: 0.3 | I40: =1/(G40*H40) -> 13.333333 | J40: 1 | K40: Ø | L40: 6 | M40: =VLOOKUP(L40,$E$64:$F$71,2,0) -> 0.222 | N40: =J40*M40 -> 0.222 | O40: =I40*N40 -> 2.96 | P40: =O40/(M40*12) -> 1.1111111 | Q40: =(2*G40+H40)*I40 -> 10.666667 | R40: =(1/(G40*H40))/0.2 -> 66.666667 | S40: 67
E41: 35 | F41: Balok 25 x 35 | G41: 0.25 | H41: 0.35 | I41: =1/(G41*H41) -> 11.428571 | J41: 1 | K41: Ø | L41: 6 | M41: =VLOOKUP(L41,$E$64:$F$71,2,0) -> 0.222 | N41: =J41*M41 -> 0.222 | O41: =I41*N41 -> 2.5371429 | P41: =O41/(M41*12) -> 0.95238095 | Q41: =(2*G41+H41)*I41 -> 9.7142857 | R41: =(1/(G41*H41))/0.2 -> 57.142857 | S41: 58
E42: 36 | F42: Balok 25 x 40 | G42: 0.25 | H42: 0.4 | I42: =1/(G42*H42) -> 10 | J42: 1 | K42: Ø | L42: 6 | M42: =VLOOKUP(L42,$E$64:$F$71,2,0) -> 0.222 | N42: =J42*M42 -> 0.222 | O42: =I42*N42 -> 2.22 | P42: =O42/(M42*12) -> 0.83333333 | Q42: =(2*G42+H42)*I42 -> 9 | R42: =(1/(G42*H42))/0.2 -> 50 | S42: 50
E43: 37 | F43: Balok 25 x 45 | G43: 0.25 | H43: 0.45 | I43: =1/(G43*H43) -> 8.8888889 | J43: 1 | K43: Ø | L43: 6 | M43: =VLOOKUP(L43,$E$64:$F$71,2,0) -> 0.222 | N43: =J43*M43 -> 0.222 | O43: =I43*N43 -> 1.9733333 | P43: =O43/(M43*12) -> 0.74074074 | Q43: =(2*G43+H43)*I43 -> 8.4444444 | R43: =(1/(G43*H43))/0.2 -> 44.444444 | S43: 45
E44: 38 | F44: Balok 25 x 50 | G44: 0.25 | H44: 0.5 | I44: =1/(G44*H44) -> 8 | J44: 1 | K44: Ø | L44: 6 | M44: =VLOOKUP(L44,$E$64:$F$71,2,0) -> 0.222 | N44: =J44*M44 -> 0.222 | O44: =I44*N44 -> 1.776 | P44: =O44/(M44*12) -> 0.66666667 | Q44: =(2*G44+H44)*I44 -> 8 | R44: =(1/(G44*H44))/0.2 -> 40 | S44: 40
E45: 39 | F45: Balok 30 x 30 | G45: 0.3 | H45: 0.3 | I45: =1/(G45*H45) -> 11.111111 | J45: 1 | K45: Ø | L45: 6 | M45: =VLOOKUP(L45,$E$64:$F$71,2,0) -> 0.222 | N45: =J45*M45 -> 0.222 | O45: =I45*N45 -> 2.4666667 | P45: =O45/(M45*12) -> 0.92592593 | Q45: =(2*G45+H45)*I45 -> 10 | R45: =(1/(G45*H45))/0.2 -> 55.555556 | S45: 56
E46: 40 | F46: Balok 30 x 35 | G46: 0.3 | H46: 0.35 | I46: =1/(G46*H46) -> 9.5238095 | J46: 7 | K46: Ø | L46: 12 | M46: =VLOOKUP(L46,$E$64:$F$71,2,0) -> 0.888 | N46: =J46*M46 -> 6.216 | O46: =I46*N46 -> 59.2 | P46: =O46/(M46*12) -> 5.5555556 | Q46: =(2*G46+H46)*I46 -> 9.047619 | R46: =(1/(G46*H46))/0.2 -> 47.619048 | S46: 48
E47: 41 | F47: Balok 30 x 40 | G47: 0.3 | H47: 0.4 | I47: =1/(G47*H47) -> 8.3333333 | J47: 1 | K47: Ø | L47: 6 | M47: =VLOOKUP(L47,$E$64:$F$71,2,0) -> 0.222 | N47: =J47*M47 -> 0.222 | O47: =I47*N47 -> 1.85 | P47: =O47/(M47*12) -> 0.69444444 | Q47: =(2*G47+H47)*I47 -> 8.3333333 | R47: =(1/(G47*H47))/0.2 -> 41.666667 | S47: 42
... E52: 46 | F52: Balok 40 x 50 | G52: 0.4 | H52: 0.5 | I52: =1/(G52*H52) -> 5 | J52: 1 | K52: Ø | L52: 6 | M52: =VLOOKUP(L52,$E$64:$F$71,2,0) -> 0.222 | N52: =J52*M52 -> 0.222 | O52: =I52*N52 -> 1.11 | P52: =O52/(M52*12) -> 0.41666667 | Q52: =(2*G52+H52)*I52 -> 6.5 | R52: =(1/(G52*H52))/0.2 -> 25 | S52: 25
E53: 47 | F53: Balok ring 15x15 | G53: 0.15 | H53: 0.15 | I53: =1/(G53*H53) -> 44.444444 | J53: 4 | K53: Ø | L53: 8 | M53: =VLOOKUP(L53,$E$64:$F$71,2,0) -> 0.395 | N53: =J53*M53 -> 1.58 | O53: =I53*N53 -> 70.222222 | P53: =O53/(M53*12) -> 14.814815 | Q53: =1*(H53+H53)*I53 -> 13.333333 | R53: =(1/(G53*H53))/0.2 -> 222.22222 | S53: 223
E54: 48 | F54: Pondasi Plat | G54: 0.25 | H54: 0.09 | I54: =1/(G54+H54) -> 2.9411765 | J54: =17+30 -> 47 | K54: Ø | L54: 12 | M54: =VLOOKUP(L54,$E$64:$F$71,2,0) -> 0.888 | N54: =J54*M54 -> 41.736 | O54: =I54*N54 -> 122.75294 | P54: =O54/(M54*12) -> 11.519608 | Q54: =1*(H54+H54)*I54 -> 0.52941176 | R54: =(1/(G54*H54))/0.2 -> 222.22222 | S54: 223
E55: 49 | F55: Plat tebal 12 cm | G55: 1 | H55: 1 | I55: =(1/(G55*H55))+10% -> 1.1 | J55: 10 | K55: Ø | L55: 10 | M55: =VLOOKUP(L55,$E$64:$F$71,2,0) -> 0.617 | N55: =J55*M55 -> 6.17 | O55: =I55*N55 -> 6.787 | P55: =O55/(M55*12) -> 0.91666667 | Q55: =1*(H55+H55)*I55 -> 2.2 | R55: =(1/(G55*H55))/0.2 -> 5 | S55: 5
E56: 50 | F56: Tangga Beton | G56: 0.12 | H56: 0.18 | I56: =1/((((G56+H56)/2)*0.27)*0.97) -> 25.455008 | J56: 19 | K56: Ø | L56: 10 | M56: =VLOOKUP(L56,$E$64:$F$71,2,0) -> 0.617 | N56: =J56*M56 -> 11.723 | O56: =I56*N56 -> 298.40906 | P56: =O56/(M56*12) -> 40.303763 | Q56: =1*(H56+H56)*I56 -> 9.163803 | R56: =(1/(G56*H56))/0.2 -> 231.48148 | S56: 232
E57: 51 | F57: Balok gantung 15cmx25cm | G57: 0.15 | H57: 0.25 | I57: =1/(G57*H57) -> 26.666667 | J57: 1 | K57: Ø | L57: 10 | M57: =VLOOKUP(L57,$E$64:$F$71,2,0) -> 0.617 | N57: =J57*M57 -> 0.617 | O57: =I57*N57 -> 16.453333 | P57: =O57/(M57*12) -> 2.2222222 | Q57: =(G57+2*H57)*I57 -> 17.333333 | R57: =(1/(G57*H57))/0.2 -> 133.33333 | S57: 134
E58: 52 | F58: Balok gantung 15cmx30cm | G58: 0.15 | H58: 0.3 | I58: =1/(G58*H58) -> 22.222222 | J58: 1 | K58: Ø | L58: 10 | M58: =VLOOKUP(L58,$E$64:$F$71,2,0) -> 0.617 | N58: =J58*M58 -> 0.617 | O58: =I58*N58 -> 13.711111 | P58: =O58/(M58*12) -> 1.8518519 | Q58: =(G58+2*H58)*I58 -> 16.666667 | R58: =(1/(G58*H58))/0.2 -> 111.11111 | S58: 112
E59: 53 | F59: Plat deck 50 cm | G59: 0.5 | H59: 0.1 | I59: =1/(G59*H59) -> 20 | J59: 1 | K59: Ø | L59: 8 | M59: =VLOOKUP(L59,$E$64:$F$71,2,0) -> 0.395 | N59: =J59*(G59+0.03)*M59 -> 0.20935 | O59: =I59*N59 -> 4.187 | P59: =O59/(M59*12) -> 0.88333333 | Q59: =1*(G59+2*H59)*I59 -> 14 | R59: =(1/(G59*H59))/0.2 -> 100 | S59: 100
...

Sheet BOBOT PEKERJAAN
E2: BOBOT PEKERJAAN
E4: No | F4: Uraian Pekerjaan | G4: Satuan | H4: Volume | I4: Harga (Rp) | K4: Bobot (%)
I5: Satuan (Rp) | J5: Jumlah (Rp)
E6: 1 | F6: 2 | G6: 3 | H6: 4 | I6: 5 | J6: 6 = 4x5 | K6: 7
E7: I | F7: PEKERJAAN PERSIAPAN
E8: 1 | F8: Pembersihan Lahan | G8: M² | H8: =VLOOKUP(F8,RekapVolume,3,FALSE) -> 200 | I8: =HSP!J14 -> 23100 | J8: =H8*I8 -> 4620000 | K8: =J8/$J$117*100 -> 1.544014
E9: 2 | F9: Pemasangan Bouwplank | G9: M¹ | H9: =VLOOKUP(F9,RekapVolume,3,FALSE) -> 48 | I9: =HSP!J10 -> 92990 | J9: =H9*I9 -> 4463520 | K9: =J9/$J$117*100 -> 1.491718
E10: 3 | F10: Penyediaan Air Kerja | G10: LS | H10: =VLOOKUP(F10,RekapVolume,3,FALSE) -> 1 | I10: 500000 | J10: =H10*I10 -> 500000 | K10: =J10/$J$117*100 -> 0.16710108
E11: 4 | F11: Administrasi & Dokumentasi | G11: LS | H11: =VLOOKUP(F11,RekapVolume,3,FALSE) -> 1 | I11: 500000 | J11: =H11*I11 -> 500000 | K11: =J11/$J$117*100 -> 0.16710108
I12: Jumlah I | J12: =SUM(J8:J11) -> 10083520 | K12: =SUM(K8:K11) -> 3.3699342
E13: II | F13: PEKERJAAN GALIAN TANAH & URUGAN
E14: 1 | F14: Galian Tanah Pondasi | G14: M³ | H14: =VLOOKUP(F14,RekapVolume,3,FALSE) -> 30.7125 | I14: =HSP!J25 -> 107800 | J14: =H14*I14 -> 3310807.5 | K14: =J14/$J$117*100 -> 1.106479
E15: 2 | F15: Urugan Tanah Kembali | G15: M³ | H15: =VLOOKUP(F15,RekapVolume,3,FALSE) -> 26.878125 | I15: =HSP!J33 -> 39050 | J15: =H15*I15 -> 1049590.8 | K15: =J15/$J$117*100 -> 0.35077551
E16: 3 | F16: Urugan Pasir Dibawah Pondasi | G16: M³ | H16: =VLOOKUP(F16,RekapVolume,3,FALSE) -> 2.025 | I16: =HSP!J35 -> 440426 | J16: =H16*I16 -> 891862.65 | K16: =J16/$J$117*100 -> 0.29806242
E17: 4 | F17: Urugan Pasir Dibawah Lantai | G17: M³ | H17: =VLOOKUP(F17,RekapVolume,3,FALSE) -> 4.8 | I17: =HSP!J35 -> 440426 | J17: =H17*I17 -> 2114044.8 | K17: =J17/$J$117*100 -> 0.70651834
I18: Jumlah II | J18: =SUM(J14:J17) -> 7366305.7 | K18: =SUM(K14:K17) -> 2.4618353
E19: III | F19: PEKERJAAN PASANGAN & PLESTERAN
E20: 1 | F20: Pasangan Batu Kosong/Aanstamping | G20: M³ | H20: =VLOOKUP(F20,RekapVolume,3,FALSE) -> 6.075 | I20: =HSP!J49 -> 885381 | J20: =H20*I20 -> 5378689.6 | K20: =J20/$J$117*100 -> 1.7975697
E21: 2 | F21: Pasangan Pondasi Batu Gunung | G21: M³ | H21: =VLOOKUP(F21,RekapVolume,3,FALSE) -> 18 | I21: =HSP!J41 -> 1467001 | J21: =H21*I21 -> 26406018 | K21: =J21/$J$117*100 -> 8.8249483
E22: 3 | F22: Pasangan Batu Bata | G22: M² | H22: =VLOOKUP(F22,RekapVolume,3,FALSE) -> 72.1 | I22: =HSP!J154 -> 178223 | J22: =H22*I22 -> 12849878 | K22: =J22/$J$117*100 -> 4.2944571
E23: 4 | F23: Plesteran Dinding | G23: M² | H23: =VLOOKUP(F23,RekapVolume,3,FALSE) -> 135.23 | I23: =HSP!J178 -> 89498 | J23: =H23*I23 -> 12102815 | K23: =J23/$J$117*100 -> 4.0447868
E24: 5 | F24: Acian Dinding | G24: M² | H24: =VLOOKUP(F24,RekapVolume,3,FALSE) -> 135.23 | I24: =HSP!J200 -> 54406 | J24: =H24*I24 -> 7357323.4 | K24: =J24/$J$117*100 -> 2.4588334
I25: Jumlah III | J25: =SUM(J20:J24) -> 64094724 | K25: =SUM(K20:K24) -> 21.420595
E26: IV | F26: PEKERJAAN BETON
E27: 1 | F27: Cor Beton Sloof 20x25 cm
F28: a. Pembesian | G28: Kg | H28: ='REKAP VOLUME'!H27 -> 189.58125 | I28: =HSP!J71/10 -> 17691.7 | J28: =H28*I28 -> 3354014.6 | K28: =J28/$J$117*100 -> 1.1209189
F29: b. Bekisting | G29: M² | H29: ='REKAP VOLUME'!H28 -> 22.5 | I29: =HSP!J75 -> 356765 | J29: =H29*I29 -> 8027212.5 | K29: =J29/$J$117*100 -> 2.6827118
F30: c. Beton | G30: M³ | H30: ='REKAP VOLUME'!H29 -> 2.25 | I30: =HSP!J61 -> 1802958 | J30: =H30*I30 -> 4056655.5 | K30: =J30/$J$117*100 -> 1.355743
E31: 2 | F31: Cor Kolom Praktis 15x15 cm
F32: a. Pembesian | G32: Kg | H32: ='REKAP VOLUME'!H31 -> 156.42833 | I32: =HSP!J71/10 -> 17691.7 | J32: =H32*I32 -> 2767483.1 | K32: =J32/$J$117*100 -> 0.92489885
F33: b. Bekisting | G33: M² | H33: ='REKAP VOLUME'!H32 -> 20.4 | I33: =HSP!J75 -> 356765 | J33: =H33*I33 -> 7278006 | K33: =J33/$J$117*100 -> 2.4323253
F34: c. Beton | G34: M³ | H34: ='REKAP VOLUME'!H33 -> 1.53 | I34: =HSP!J61 -> 1802958 | J34: =H34*I34 -> 2758525.7 | K34: =J34/$J$117*100 -> 0.92190526
A35: www.rabotomatis.com | E35: 3 | F35: Cor Ring Balk 15x15 cm
F36: a. Pembesian | G36: Kg | H36: ='REKAP VOLUME'!H35 -> 103.51875 | I36: =HSP!J71/10 -> 17691.7 | J36: =H36*I36 -> 1831422.7 | K36: =J36/$J$117*100 -> 0.61206541
